Workbook
Name 宿泊設定: IF('[1]2.【入力】希望調整表'!A1048472="入所",1,IF('[1]2.【入力】希望調整表'!XFD1048472="退所",'[1]2.【入力】希望調整表'!XFD1-1,'[1]2.【入力】希望調整表'!XFD1))
Name 前日空欄採番: IF(OR(宿泊欄自動割当!A1048547=退所日,宿泊欄自動割当!A1048536=""),(COUNTIF(宿泊欄自動割当!A$23:A1048547,退所日)+COUNTIF(宿泊欄自動割当!A$12:A1048536,""))+100,0)
Name 退所日: 【設定】基本情報!$A$22
Name 通いの日: 【設定】基本情報!$A$23
Name 当日の宿泊状況獲得: IFERROR(INDEX(【入力・帳票】ベッド表!XDY$83:XDY$111,MATCH(宿泊欄自動割当!XDX1048545,【入力・帳票】ベッド表!$B$83:$B$111,0)),0)
Name 当日入所インデックス作成: IF(宿泊欄自動割当!AH1=入所日,COUNTIF(宿泊欄自動割当!AH$33:AH1,入所日)+100,-1)
Name 日ごとの泊りIDX作成: IFERROR(INDEX(【入力】調整表!$D$288:$AI$319,MATCH(【入力・帳票】ベッド表!$B1,【入力】調整表!$B$288:$B$319,0),【入力・帳票】ベッド表!A$49),0)
Name 入所日: 【設定】基本情報!$A$20
Name 入所日の行割り当て: IF(宿泊欄自動割当!A1048567>0,MATCH(宿泊欄自動割当!A1048567,宿泊欄自動割当!XFD$53:XFD$61,0),宿泊欄自動割当!A1048567)
Name 泊り状況テーブル作成: IFERROR(INDEX(【入力】調整表!$E$113:$AI$176,【入力・帳票】ベッド表!$C1,【入力・帳票】ベッド表!A$49-1),0)
Name 訪問希望の値: IFERROR(INDEX('[1]2.【入力】希望調整表'!$D$111:$AH$206,'[1]5.【入力】訪問調整'!$B1,COLUMN()-2),-1)
Name 訪問設定最小値: 【設定】基本情報!$A$24
Name 訪問設定最大値: 【設定】基本情報!$A$25
Name 訪問送迎の値: IFERROR(INDEX('[1]4.【入力】通い調整'!$B$113:$AF$144,'[1]5.【入力】訪問調整'!$AJ1,COLUMN()-2),-1)
Name 翌日の宿泊状況獲得: IFERROR(INDEX(【入力・帳票】ベッド表!XDZ$83:XDZ$111,MATCH(宿泊欄自動割当!XDX1048555,【入力・帳票】ベッド表!$B$83:$B$111,0)),0)
Name 翌日退所確認: IF(INDEX(宿泊欄自動割当!AH$23:AH$31,MATCH(宿泊欄自動割当!A1048566,宿泊欄自動割当!A$1:A$9,0))=退所日,退所日,-1)
Name 来ない日: 【設定】基本情報!$A$19
Name 略名選択範囲: OFFSET('[1]0.【登録】利用者台帳'!$B$2,,,COUNTA('[1]0.【登録】利用者台帳'!$B$2:$B$33,1))
Name 略名選択範囲: OFFSET(【入力】利用者台帳!$B$3,,,COUNTA(【入力】利用者台帳!$B$3:$B$34),1)
Name 連泊日: 【設定】基本情報!$A$21

Sheet 【設定】基本情報
A1: 事業所名 | B1: 小規模多機能ホーム方南
A2: 対象年 | B2: 2025
A3: 対象月 | B3: 12
A4: 月の日数 | B4: =【帳票】予定希望票!$AX$2 -> 31
A5: 通い定員 | B5: 18
A6: 泊り定員 | B6: 9
A9: 要介護度 | B9: 訪問件数計算用（介護以上フラグ値）
A10: 要介護1 | B10: 1
A11: 要介護2 | B11: 1
A12: 要介護3 | B12: 1
A13: 要介護4 | B13: 1
A14: 要介護5 | B14: 1
A15: 要支援1 | B15: 0
A16: 要支援2 | B16: 0
A18: 定数値 | B18: 定数名（名前定義してます） | C18: 日報データ表示 | D18: 日報・訪問送迎内容表示の初期値 | E18: 送迎訪問 回数ﾃﾞﾌｫ
A19: 0 | B19: 来ない日 | E19: 0
A20: 11 | B20: 入所日 | C20: 入所 | D20: 朝 送り出し | E20: 1
A21: 12 | B21: 連泊日 | C21: 泊り | D21: ="" | E21: 0
A22: 13 | B22: 退所日 | C22: 退所 | D22: 夕 迎え入れ | E22: 1
A23: 14 | B23: 通いの日 | C23: 通い | D23: 朝 送り出し／夕 迎え入れ | E23: 2
A24: 1 | B24: 訪問設定最小値
A25: 10 | B25: 訪問設定最大値

Sheet 【入力】利用者台帳
A2: 0 | B2: 略名 | C2: 氏名 | D2: 介護度 | E2: 送迎 訪問 | F2: 固定申し送り事項 （氏名欄）
A3: =A2+1 -> 1 | B3: 青砥 | C3: 青砥 美秋
A4: =A3+1 -> 2 | B4: 安藤 | C4: 安藤 敏子 | D4: 要介護5 | E4: ✓
A5: =A4+1 -> 3 | B5: 石井 | C5: 石井 さち子 | D5: 要介護3
A6: =A5+1 -> 4 | B6: 石橋 | C6: 石橋 冨士代 | D6: 要介護1
A7: =A6+1 -> 5 | B7: 伊シ | C7: 伊藤 シゲ | D7: 要介護3 | E7: ✓
A8: =A7+1 -> 6 | B8: 伊ミ | C8: 伊藤 ミツ | D8: 要介護3 | E8: ✓
A9: =A8+1 -> 7 | B9: 岩永 | C9: 岩永 里子 | D9: 要介護3 | E9: ✓
A10: =A9+1 -> 8 | B10: 川原 | C10: 川原 克子 | D10: 要介護4
A11: =A10+1 -> 9 | B11: 工藤 | C11: 工藤 信代 | D11: 要介護2
A12: =A11+1 -> 10 | B12: 坂本 | C12: 坂本 みつ子 | D12: 要介護1
A13: =A12+1 -> 11 | B13: 佐々 | C13: 佐々木敦子 | D13: 要介護4 | E13: ✓
A14: =A13+1 -> 12 | B14: 澤井 | C14: 澤井 節子 | D14: 要介護1
A15: =A14+1 -> 13 | B15: 澤登 | C15: 澤登 佳子 | D15: 要介護2 | E15: ✓
A16: =A15+1 -> 14 | B16: 白井 | C16: 白井 加都子 | D16: 要介護1 | E16: ✓
A17: =A16+1 -> 15 | B17: 鈴木 | C17: 鈴木 育代 | D17: 要介護4 | E17: ✓
A18: =A17+1 -> 16 | B18: 高久 | C18: 高久 直美 | D18: 要介護2
A19: =A18+1 -> 17 | B19: 高橋 | C19: 高橋 ハツコ | D19: 要介護1 | E19: ✓
A20: =A19+1 -> 18 | B20: 田中 | C20: 田中 保行 | D20: 要介護3
A21: =A20+1 -> 19 | B21: 土肥 | C21: 土肥 俊江 | D21: 要支援2
A22: =A21+1 -> 20 | B22: 仲里 | C22: 仲里 克彦 | D22: 要介護4 | E22: ✓
A23: =A22+1 -> 21 | B23: 二宮 | C23: 二宮 身延 | D23: 要介護4 | E23: ✓
A24: =A23+1 -> 22 | B24: 初谷 | C24: 初谷 キイ | D24: 要介護2
A25: =A24+1 -> 23 | B25: 星野 | C25: 星野 仁江 | D25: 要介護1
A26: =A25+1 -> 24 | B26: 堀節 | C26: 堀田 節子 | D26: 要介護2 | E26: ✓
A27: =A26+1 -> 25 | B27: 宮本 | C27: 宮本 美代子 | D27: 要介護1
A28: =A27+1 -> 26 | B28: 山地 | C28: 山地 チヨ | D28: 要介護2 | E28: ✓
A29: =A28+1 -> 27 | B29: 山本 | C29: 山本 令郎 | D29: 要介護2
A30: =A29+1 -> 28 | B30: 吉田 | C30: 吉田 良子 | D30: 要介護4
A31: =A30+1 -> 29 | B31: 渡邊 | C31: 渡邊 良子 | D31: 要介護3 | E31: ✓
A32: =A31+1 -> 30
A33: =A32+1 -> 31
A34: =A33+1 -> 32
B36: (名) | C36: 略名選択範囲 | D36: =OFFSET('0.【登録】利用者台帳'!$B$2,,,COUNTA('0.【登録】利用者台帳'!$B$2:$B$33),1)

Sheet 【帳票】予定希望票
A1: =【設定】基本情報!$B$1 -> 小規模多機能ホーム方南 | R1: カレンダー作成処理用 | AX1: =IF($C$8=12,DATE($B$8+1,1,1),DATE($B$8,$C$8+1,1)) -> 46023
R2: 日 | S2: =DATE($B$8,$C$8,1) -> 45992 | T2: =S2+1 -> 45993 | U2: =T2+1 -> 45994 | V2: =U2+1 -> 45995 | W2: =V2+1 -> 45996 | X2: =W2+1 -> 45997 | Y2: =X2+1 -> 45998 | Z2: =Y2+1 -> 45999 | AA2: =Z2+1 -> 46000 | ... AW2: =AV2+1 -> 46022 | AX2: =$AX$1-$S$2 -> 31
R3: 曜日 | S3: =WEEKDAY(S2) -> 2 | T3: =WEEKDAY(T2) -> 3 | U3: =WEEKDAY(U2) -> 4 | V3: =WEEKDAY(V2) -> 5 | W3: =WEEKDAY(W2) -> 6 | X3: =WEEKDAY(X2) -> 7 | Y3: =WEEKDAY(Y2) -> 1 | Z3: =WEEKDAY(Z2) -> 2 | ... AW3: =WEEKDAY(AW2) -> 4
C5: 様 | T5: 1 | U5: 2 | V5: 3 | W5: 4 | X5: 5 | Y5: 6 | Z5: 7
R6: 起点チェック | T6: =IF($S$3=T5,1,"") | U6: =IF($S$3=U5,1,"") -> 1 | V6: =IF($S$3=V5,1,"") | W6: =IF($S$3=W5,1,"") | X6: =IF($S$3=X5,1,"") | Y6: =IF($S$3=Y5,1,"") | Z6: =IF($S$3=Z5,1,"")
S7: 0 | T7: =IF(OR(T6=1,S7>0),S7+1,0) -> 0 | U7: =IF(OR(U6=1,T7>0),T7+1,0) -> 1 | V7: =IF(OR(V6=1,U7>0),U7+1,0) -> 2 | W7: =IF(OR(W6=1,V7>0),V7+1,0) -> 3 | X7: =IF(OR(X6=1,W7>0),W7+1,0) -> 4 | Y7: =IF(OR(Y6=1,X7>0),X7+1,0) -> 5 | Z7: =IF(OR(Z6=1,Y7>0),Y7+1,0) -> 6
B8: =【設定】基本情報!$B$2 -> 2025 | C8: =【設定】基本情報!$B$3 -> 12 | D8: 希望表 | T8: =Z7+1 -> 7 | U8: =T8+1 -> 8 | V8: =U8+1 -> 9 | W8: =V8+1 -> 10 | X8: =W8+1 -> 11 | Y8: =X8+1 -> 12 | Z8: =Y8+1 -> 13
T9: =Z8+1 -> 14 | U9: =T9+1 -> 15 | V9: =U9+1 -> 16 | W9: =V9+1 -> 17 | X9: =W9+1 -> 18 | Y9: =X9+1 -> 19 | Z9: =Y9+1 -> 20
T10: =Z9+1 -> 21 | U10: =T10+1 -> 22 | V10: =U10+1 -> 23 | W10: =V10+1 -> 24 | X10: =W10+1 -> 25 | Y10: =X10+1 -> 26 | Z10: =Y10+1 -> 27
B11: 日 | C11: 月 | D11: 火 | E11: 水 | F11: 木 | G11: 金 | H11: 土 | T11: =IF(Z10+1>$AX$2,0,Z10+1) -> 28 | U11: =IF(OR(T11=0,T11+1>$AX$2),0,T11+1) -> 29 | V11: =IF(OR(U11=0,U11+1>$AX$2),0,U11+1) -> 30 | W11: =IF(OR(V11=0,V11+1>$AX$2),0,V11+1) -> 31 | X11: =IF(OR(W11=0,W11+1>$AX$2),0,W11+1) -> 0 | Y11: =IF(OR(X11=0,X11+1>$AX$2),0,X11+1) -> 0 | Z11: =IF(OR(Y11=0,Y11+1>$AX$2),0,Y11+1) -> 0
B12: =IF(T7<>0,T7,"") | C12: =IF(U7<>0,U7,"") -> 1 | D12: =IF(V7<>0,V7,"") -> 2 | E12: =IF(W7<>0,W7,"") -> 3 | F12: =IF(X7<>0,X7,"") -> 4 | G12: =IF(Y7<>0,Y7,"") -> 5 | H12: =IF(Z7<>0,Z7,"") -> 6 | T12: =IF(OR(Z11=0,Z11+1>$AX$2),0,Z11+1) -> 0 | U12: =IF(OR(T12=0,T12+1>$AX$2),0,T12+1) -> 0 | V12: =IF(OR(U12=0,U12+1>$AX$2),0,U12+1) -> 0 | W12: =IF(OR(V12=0,V12+1>$AX$2),0,V12+1) -> 0 | X12: =IF(OR(W12=0,W12+1>$AX$2),0,W12+1) -> 0 | Y12: =IF(OR(X12=0,X12+1>$AX$2),0,X12+1) -> 0 | Z12: =IF(OR(Y12=0,Y12+1>$AX$2),0,Y12+1) -> 0
B16: =IF(T8<>0,T8,"") -> 7 | C16: =IF(U8<>0,U8,"") -> 8 | D16: =IF(V8<>0,V8,"") -> 9 | E16: =IF(W8<>0,W8,"") -> 10 | F16: =IF(X8<>0,X8,"") -> 11 | G16: =IF(Y8<>0,Y8,"") -> 12 | H16: =IF(Z8<>0,Z8,"") -> 13
B20: =IF(T9<>0,T9,"") -> 14 | C20: =IF(U9<>0,U9,"") -> 15 | D20: =IF(V9<>0,V9,"") -> 16 | E20: =IF(W9<>0,W9,"") -> 17 | F20: =IF(X9<>0,X9,"") -> 18 | G20: =IF(Y9<>0,Y9,"") -> 19 | H20: =IF(Z9<>0,Z9,"") -> 20
B24: =IF(T10<>0,T10,"") -> 21 | C24: =IF(U10<>0,U10,"") -> 22 | D24: =IF(V10<>0,V10,"") -> 23 | E24: =IF(W10<>0,W10,"") -> 24 | F24: =IF(X10<>0,X10,"") -> 25 | G24: =IF(Y10<>0,Y10,"") -> 26 | H24: =IF(Z10<>0,Z10,"") -> 27
B28: =IF(T11<>0,T11,"") -> 28 | C28: =IF(U11<>0,U11,"") -> 29 | D28: =IF(V11<>0,V11,"") -> 30 | E28: =IF(W11<>0,W11,"") -> 31 | F28: =IF(X11<>0,X11,"") | G28: =IF(Y11<>0,Y11,"") | H28: =IF(Z11<>0,Z11,"")
B32: =IF(T12<>0,T12,"") | C32: =IF(U12<>0,U12,"") | D32: =IF(V12<>0,V12,"") | E32: =IF(W12<>0,W12,"")
F33: 家族会:１０時～ 方南１Fデイルームです。
B37: ★皆さんの予定のすり合せのため、期限までのご提出にご協力をお願いいたします★
B40: =IF($C$8=1,12,$C$8-1) -> 11 | C40: 月５日までに、ご提出をお願いいたします。
B42: ※混雑状況により、一部宿泊をお受け出来ないことがありますので予めご了承ください。
B44: 家族懇談会： 1１月 ９日（日）
F45: 電話 ０３－５９２９－６１1５
F46: FAX ０３－５９２９－６１1７
G47: 担当 ：村上

Sheet 【入力】希望表
A1: =DATE(【設定】基本情報!$B$2,【設定】基本情報!$B$3,1) -> 45992 | E1: =$A$1 -> 45992 | F1: =E1+1 -> 45993 | G1: =F1+1 -> 45994 | H1: =G1+1 -> 45995 | I1: =H1+1 -> 45996 | J1: =I1+1 -> 45997 | K1: =J1+1 -> 45998 | L1: =K1+1 -> 45999 | M1: =L1+1 -> 46000 | ... AI1: =AH1+1 -> 46022
E2: =E1 -> 45992 | F2: =F1 -> 45993 | G2: =G1 -> 45994 | H2: =H1 -> 45995 | I2: =I1 -> 45996 | J2: =J1 -> 45997 | K2: =K1 -> 45998 | L2: =L1 -> 45999 | ... AI2: =AI1 -> 46022
A3: 希望表 | D3: 泊り | E3: =COUNTIFS($D$113:$D$176,"通泊",E$113:E$176,入所日)+COUNTIFS($D$113:$D$176,"通泊",E$113:E$176,連泊日) -> 0 | F3: =COUNTIFS($D$113:$D$176,"通泊",F$113:F$176,入所日)+COUNTIFS($D$113:$D$176,"通泊",F$113:F$176,連泊日) -> 0 | G3: =COUNTIFS($D$113:$D$176,"通泊",G$113:G$176,入所日)+COUNTIFS($D$113:$D$176,"通泊",G$113:G$176,連泊日) -> 0 | H3: =COUNTIFS($D$113:$D$176,"通泊",H$113:H$176,入所日)+COUNTIFS($D$113:$D$176,"通泊",H$113:H$176,連泊日) -> 0 | I3: =COUNTIFS($D$113:$D$176,"通泊",I$113:I$176,入所日)+COUNTIFS($D$113:$D$176,"通泊",I$113:I$176,連泊日) -> 0 | J3: =COUNTIFS($D$113:$D$176,"通泊",J$113:J$176,入所日)+COUNTIFS($D$113:$D$176,"通泊",J$113:J$176,連泊日) -> 0 | K3: =COUNTIFS($D$113:$D$176,"通泊",K$113:K$176,入所日)+COUNTIFS($D$113:$D$176,"通泊",K$113:K$176,連泊日) -> 0 | L3: =COUNTIFS($D$113:$D$176,"通泊",L$113:L$176,入所日)+COUNTIFS($D$113:$D$176,"通泊",L$113:L$176,連泊日) -> 0 | ... AI3: =COUNTIFS($D$113:$D$176,"通泊",AI$113:AI$176,入所日)+COUNTIFS($D$113:$D$176,"通泊",AI$113:AI$176,連泊日) -> 0
D4: 通い | E4: =E$3+COUNTIFS($D$113:$D$176,"通泊",E$113:E$176,退所日)+COUNTIFS($D$113:$D$176,"通泊",E$113:E$176,通いの日) -> 0 | F4: =F$3+COUNTIFS($D$113:$D$176,"通泊",F$113:F$176,退所日)+COUNTIFS($D$113:$D$176,"通泊",F$113:F$176,通いの日) -> 0 | G4: =G$3+COUNTIFS($D$113:$D$176,"通泊",G$113:G$176,退所日)+COUNTIFS($D$113:$D$176,"通泊",G$113:G$176,通いの日) -> 0 | H4: =H$3+COUNTIFS($D$113:$D$176,"通泊",H$113:H$176,退所日)+COUNTIFS($D$113:$D$176,"通泊",H$113:H$176,通いの日) -> 0 | I4: =I$3+COUNTIFS($D$113:$D$176,"通泊",I$113:I$176,退所日)+COUNTIFS($D$113:$D$176,"通泊",I$113:I$176,通いの日) -> 0 | J4: =J$3+COUNTIFS($D$113:$D$176,"通泊",J$113:J$176,退所日)+COUNTIFS($D$113:$D$176,"通泊",J$113:J$176,通いの日) -> 0 | K4: =K$3+COUNTIFS($D$113:$D$176,"通泊",K$113:K$176,退所日)+COUNTIFS($D$113:$D$176,"通泊",K$113:K$176,通いの日) -> 0 | L4: =L$3+COUNTIFS($D$113:$D$176,"通泊",L$113:L$176,退所日)+COUNTIFS($D$113:$D$176,"通泊",L$113:L$176,通いの日) -> 0 | ... AI4: =AI$3+COUNTIFS($D$113:$D$176,"通泊",AI$113:AI$176,退所日)+COUNTIFS($D$113:$D$176,"通泊",AI$113:AI$176,通いの日) -> 0
D5: 訪問 | E5: =SUMIF($D$113:$D$176,"訪問",E113:E$176) -> 0 | F5: =SUMIF($D$113:$D$176,"訪問",F113:F$176) -> 0 | G5: =SUMIF($D$113:$D$176,"訪問",G113:G$176) -> 0 | H5: =SUMIF($D$113:$D$176,"訪問",H113:H$176) -> 0 | I5: =SUMIF($D$113:$D$176,"訪問",I113:I$176) -> #REF! | J5: =SUMIF($D$113:$D$176,"訪問",J113:J$176) -> 0 | K5: =SUMIF($D$113:$D$176,"訪問",K113:K$176) -> 0 | L5: =SUMIF($D$113:$D$176,"訪問",L113:L$176) -> 0 | ... AI5: =SUMIF($D$113:$D$176,"訪問",AI113:AI$176) -> 0
A6: =B6 -> 青砥 美秋 | B6: =IF(ISBLANK(【入力】利用者台帳!C3),"",【入力】利用者台帳!C3) -> 青砥 美秋 | C6: =IF(ISBLANK(【入力】利用者台帳!D3),"",【入力】利用者台帳!D3) | D6: 通泊
B7: =IF(ISBLANK(【入力】利用者台帳!C3),"",【入力】利用者台帳!C3) -> 青砥 美秋 | C7: =IF(ISBLANK(【入力】利用者台帳!D3),"",【入力】利用者台帳!D3) | D7: 訪問
A8: =B8 -> 安藤 敏子 | B8: =IF(ISBLANK(【入力】利用者台帳!C4),"",【入力】利用者台帳!C4) -> 安藤 敏子 | C8: =IF(ISBLANK(【入力】利用者台帳!D4),"",【入力】利用者台帳!D4) -> 要介護5 | D8: 通泊
B9: =IF(ISBLANK(【入力】利用者台帳!C4),"",【入力】利用者台帳!C4) -> 安藤 敏子 | C9: =IF(ISBLANK(【入力】利用者台帳!D4),"",【入力】利用者台帳!D4) -> 要介護5 | D9: 訪問
A10: =B10 -> 石井 さち子 | B10: =IF(ISBLANK(【入力】利用者台帳!C5),"",【入力】利用者台帳!C5) -> 石井 さち子 | C10: =IF(ISBLANK(【入力】利用者台帳!D5),"",【入力】利用者台帳!D5) -> 要介護3 | D10: 通泊
B11: =IF(ISBLANK(【入力】利用者台帳!C5),"",【入力】利用者台帳!C5) -> 石井 さち子 | C11: =IF(ISBLANK(【入力】利用者台帳!D5),"",【入力】利用者台帳!D5) -> 要介護3 | D11: 訪問
A12: =B12 -> 石橋 冨士代 | B12: =IF(ISBLANK(【入力】利用者台帳!C6),"",【入力】利用者台帳!C6) -> 石橋 冨士代 | C12: =IF(ISBLANK(【入力】利用者台帳!D6),"",【入力】利用者台帳!D6) -> 要介護1 | D12: 通泊
B13: =IF(ISBLANK(【入力】利用者台帳!C6),"",【入力】利用者台帳!C6) -> 石橋 冨士代 | C13: =IF(ISBLANK(【入力】利用者台帳!D6),"",【入力】利用者台帳!D6) -> 要介護1 | D13: 訪問
A14: =B14 -> 伊藤 シゲ | B14: =IF(ISBLANK(【入力】利用者台帳!C7),"",【入力】利用者台帳!C7) -> 伊藤 シゲ | C14: =IF(ISBLANK(【入力】利用者台帳!D7),"",【入力】利用者台帳!D7) -> 要介護3 | D14: 通泊
B15: =IF(ISBLANK(【入力】利用者台帳!C7),"",【入力】利用者台帳!C7) -> 伊藤 シゲ | C15: =IF(ISBLANK(【入力】利用者台帳!D7),"",【入力】利用者台帳!D7) -> 要介護3 | D15: 訪問
A16: =B16 -> 伊藤 ミツ | B16: =IF(ISBLANK(【入力】利用者台帳!C8),"",【入力】利用者台帳!C8) -> 伊藤 ミツ | C16: =IF(ISBLANK(【入力】利用者台帳!D8),"",【入力】利用者台帳!D8) -> 要介護3 | D16: 通泊
B17: =IF(ISBLANK(【入力】利用者台帳!C8),"",【入力】利用者台帳!C8) -> 伊藤 ミツ | C17: =IF(ISBLANK(【入力】利用者台帳!D8),"",【入力】利用者台帳!D8) -> 要介護3 | D17: 訪問
A18: =B18 -> 岩永 里子 | B18: =IF(ISBLANK(【入力】利用者台帳!C9),"",【入力】利用者台帳!C9) -> 岩永 里子 | C18: =IF(ISBLANK(【入力】利用者台帳!D9),"",【入力】利用者台帳!D9) -> 要介護3 | D18: 通泊
B19: =IF(ISBLANK(【入力】利用者台帳!C9),"",【入力】利用者台帳!C9) -> 岩永 里子 | C19: =IF(ISBLANK(【入力】利用者台帳!D9),"",【入力】利用者台帳!D9) -> 要介護3 | D19: 訪問
A20: =B20 -> 川原 克子 | B20: =IF(ISBLANK(【入力】利用者台帳!C10),"",【入力】利用者台帳!C10) -> 川原 克子 | C20: =IF(ISBLANK(【入力】利用者台帳!D10),"",【入力】利用者台帳!D10) -> 要介護4 | D20: 通泊
B21: =IF(ISBLANK(【入力】利用者台帳!C10),"",【入力】利用者台帳!C10) -> 川原 克子 | C21: =IF(ISBLANK(【入力】利用者台帳!D10),"",【入力】利用者台帳!D10) -> 要介護4 | D21: 訪問
A22: =B22 -> 工藤 信代 | B22: =IF(ISBLANK(【入力】利用者台帳!C11),"",【入力】利用者台帳!C11) -> 工藤 信代 | C22: =IF(ISBLANK(【入力】利用者台帳!D11),"",【入力】利用者台帳!D11) -> 要介護2 | D22: 通泊
B23: =IF(ISBLANK(【入力】利用者台帳!C11),"",【入力】利用者台帳!C11) -> 工藤 信代 | C23: =IF(ISBLANK(【入力】利用者台帳!D11),"",【入力】利用者台帳!D11) -> 要介護2 | D23: 訪問
A24: =B24 -> 坂本 みつ子 | B24: =IF(ISBLANK(【入力】利用者台帳!C12),"",【入力】利用者台帳!C12) -> 坂本 みつ子 | C24: =IF(ISBLANK(【入力】利用者台帳!D12),"",【入力】利用者台帳!D12) -> 要介護1 | D24: 通泊
B25: =IF(ISBLANK(【入力】利用者台帳!C12),"",【入力】利用者台帳!C12) -> 坂本 みつ子 | C25: =IF(ISBLANK(【入力】利用者台帳!D12),"",【入力】利用者台帳!D12) -> 要介護1 | D25: 訪問
A26: =B26 -> 佐々木敦子 | B26: =IF(ISBLANK(【入力】利用者台帳!C13),"",【入力】利用者台帳!C13) -> 佐々木敦子 | C26: =IF(ISBLANK(【入力】利用者台帳!D13),"",【入力】利用者台帳!D13) -> 要介護4 | D26: 通泊
B27: =IF(ISBLANK(【入力】利用者台帳!C13),"",【入力】利用者台帳!C13) -> 佐々木敦子 | C27: =IF(ISBLANK(【入力】利用者台帳!D13),"",【入力】利用者台帳!D13) -> 要介護4 | D27: 訪問
A28: =B28 -> 澤井 節子 | B28: =IF(ISBLANK(【入力】利用者台帳!C14),"",【入力】利用者台帳!C14) -> 澤井 節子 | C28: =IF(ISBLANK(【入力】利用者台帳!D14),"",【入力】利用者台帳!D14) -> 要介護1 | D28: 通泊
B29: =IF(ISBLANK(【入力】利用者台帳!C14),"",【入力】利用者台帳!C14) -> 澤井 節子 | C29: =IF(ISBLANK(【入力】利用者台帳!D14),"",【入力】利用者台帳!D14) -> 要介護1 | D29: 訪問
A30: =B30 -> 澤登 佳子 | B30: =IF(ISBLANK(【入力】利用者台帳!C15),"",【入力】利用者台帳!C15) -> 澤登 佳子 | C30: =IF(ISBLANK(【入力】利用者台帳!D15),"",【入力】利用者台帳!D15) -> 要介護2 | D30: 通泊
B31: =IF(ISBLANK(【入力】利用者台帳!C15),"",【入力】利用者台帳!C15) -> 澤登 佳子 | C31: =IF(ISBLANK(【入力】利用者台帳!D15),"",【入力】利用者台帳!D15) -> 要介護2 | D31: 訪問
A32: =B32 -> 白井 加都子 | B32: =IF(ISBLANK(【入力】利用者台帳!C16),"",【入力】利用者台帳!C16) -> 白井 加都子 | C32: =IF(ISBLANK(【入力】利用者台帳!D16),"",【入力】利用者台帳!D16) -> 要介護1 | D32: 通泊
B33: =IF(ISBLANK(【入力】利用者台帳!C16),"",【入力】利用者台帳!C16) -> 白井 加都子 | C33: =IF(ISBLANK(【入力】利用者台帳!D16),"",【入力】利用者台帳!D16) -> 要介護1 | D33: 訪問
A34: =B34 -> 鈴木 育代 | B34: =IF(ISBLANK(【入力】利用者台帳!C17),"",【入力】利用者台帳!C17) -> 鈴木 育代 | C34: =IF(ISBLANK(【入力】利用者台帳!D17),"",【入力】利用者台帳!D17) -> 要介護4 | D34: 通泊
B35: =IF(ISBLANK(【入力】利用者台帳!C17),"",【入力】利用者台帳!C17) -> 鈴木 育代 | C35: =IF(ISBLANK(【入力】利用者台帳!D17),"",【入力】利用者台帳!D17) -> 要介護4 | D35: 訪問
A36: =B36 -> 高久 直美 | B36: =IF(ISBLANK(【入力】利用者台帳!C18),"",【入力】利用者台帳!C18) -> 高久 直美 | C36: =IF(ISBLANK(【入力】利用者台帳!D18),"",【入力】利用者台帳!D18) -> 要介護2 | D36: 通泊
B37: =IF(ISBLANK(【入力】利用者台帳!C18),"",【入力】利用者台帳!C18) -> 高久 直美 | C37: =IF(ISBLANK(【入力】利用者台帳!D18),"",【入力】利用者台帳!D18) -> 要介護2 | D37: 訪問
A38: =B38 -> 高橋 ハツコ | B38: =IF(ISBLANK(【入力】利用者台帳!C19),"",【入力】利用者台帳!C19) -> 高橋 ハツコ | C38: =IF(ISBLANK(【入力】利用者台帳!D19),"",【入力】利用者台帳!D19) -> 要介護1 | D38: 通泊
B39: =IF(ISBLANK(【入力】利用者台帳!C19),"",【入力】利用者台帳!C19) -> 高橋 ハツコ | C39: =IF(ISBLANK(【入力】利用者台帳!D19),"",【入力】利用者台帳!D19) -> 要介護1 | D39: 訪問
A40: =B40 -> 田中 保行 | B40: =IF(ISBLANK(【入力】利用者台帳!C20),"",【入力】利用者台帳!C20) -> 田中 保行 | C40: =IF(ISBLANK(【入力】利用者台帳!D20),"",【入力】利用者台帳!D20) -> 要介護3 | D40: 通泊
...

Sheet 【入力】調整表
A1: =DATE(【設定】基本情報!$B$2,【設定】基本情報!$B$3,1) -> 45992 | E1: =$A$1 -> 45992 | F1: =E1+1 -> 45993 | G1: =F1+1 -> 45994 | H1: =G1+1 -> 45995 | I1: =H1+1 -> 45996 | J1: =I1+1 -> 45997 | K1: =J1+1 -> 45998 | L1: =K1+1 -> 45999 | M1: =L1+1 -> 46000 | ... AI1: =AH1+1 -> 46022
E2: =E1 -> 45992 | F2: =F1 -> 45993 | G2: =G1 -> 45994 | H2: =H1 -> 45995 | I2: =I1 -> 45996 | J2: =J1 -> 45997 | K2: =K1 -> 45998 | L2: =L1 -> 45999 | ... AI2: =AI1 -> 46022 | AJ2: 合計
A3: 調整表 | D3: 泊り | E3: =COUNTIFS($D$113:$D$176,"通泊",E$113:E$176,入所日)+COUNTIFS($D$113:$D$176,"通泊",E$113:E$176,連泊日) -> 9 | F3: =COUNTIFS($D$113:$D$176,"通泊",F$113:F$176,入所日)+COUNTIFS($D$113:$D$176,"通泊",F$113:F$176,連泊日) -> 10 | G3: =COUNTIFS($D$113:$D$176,"通泊",G$113:G$176,入所日)+COUNTIFS($D$113:$D$176,"通泊",G$113:G$176,連泊日) -> 10 | H3: =COUNTIFS($D$113:$D$176,"通泊",H$113:H$176,入所日)+COUNTIFS($D$113:$D$176,"通泊",H$113:H$176,連泊日) -> 9 | I3: =COUNTIFS($D$113:$D$176,"通泊",I$113:I$176,入所日)+COUNTIFS($D$113:$D$176,"通泊",I$113:I$176,連泊日) -> 9 | J3: =COUNTIFS($D$113:$D$176,"通泊",J$113:J$176,入所日)+COUNTIFS($D$113:$D$176,"通泊",J$113:J$176,連泊日) -> 10 | K3: =COUNTIFS($D$113:$D$176,"通泊",K$113:K$176,入所日)+COUNTIFS($D$113:$D$176,"通泊",K$113:K$176,連泊日) -> 10 | L3: =COUNTIFS($D$113:$D$176,"通泊",L$113:L$176,入所日)+COUNTIFS($D$113:$D$176,"通泊",L$113:L$176,連泊日) -> 10 | ... AI3: =COUNTIFS($D$113:$D$176,"通泊",AI$113:AI$176,入所日)+COUNTIFS($D$113:$D$176,"通泊",AI$113:AI$176,連泊日) -> 8 | AJ3: =SUM(OFFSET($E3,0,0,1,【設定】基本情報!$B$4)) -> 256
D4: 通い | E4: =E$3+COUNTIFS($D$113:$D$176,"通泊",E$113:E$176,退所日)+COUNTIFS($D$113:$D$176,"通泊",E$113:E$176,通いの日) -> 19 | F4: =F$3+COUNTIFS($D$113:$D$176,"通泊",F$113:F$176,退所日)+COUNTIFS($D$113:$D$176,"通泊",F$113:F$176,通いの日) -> 20 | G4: =G$3+COUNTIFS($D$113:$D$176,"通泊",G$113:G$176,退所日)+COUNTIFS($D$113:$D$176,"通泊",G$113:G$176,通いの日) -> 19 | H4: =H$3+COUNTIFS($D$113:$D$176,"通泊",H$113:H$176,退所日)+COUNTIFS($D$113:$D$176,"通泊",H$113:H$176,通いの日) -> 18 | I4: =I$3+COUNTIFS($D$113:$D$176,"通泊",I$113:I$176,退所日)+COUNTIFS($D$113:$D$176,"通泊",I$113:I$176,通いの日) -> 18 | J4: =J$3+COUNTIFS($D$113:$D$176,"通泊",J$113:J$176,退所日)+COUNTIFS($D$113:$D$176,"通泊",J$113:J$176,通いの日) -> 20 | K4: =K$3+COUNTIFS($D$113:$D$176,"通泊",K$113:K$176,退所日)+COUNTIFS($D$113:$D$176,"通泊",K$113:K$176,通いの日) -> 15 | L4: =L$3+COUNTIFS($D$113:$D$176,"通泊",L$113:L$176,退所日)+COUNTIFS($D$113:$D$176,"通泊",L$113:L$176,通いの日) -> 19 | ... AI4: =AI$3+COUNTIFS($D$113:$D$176,"通泊",AI$113:AI$176,退所日)+COUNTIFS($D$113:$D$176,"通泊",AI$113:AI$176,通いの日) -> 18 | AJ4: =SUM(OFFSET($E4,0,0,1,【設定】基本情報!$B$4)) -> 547
D5: 訪問 | E5: =SUMIF($D$113:$D$176,"訪問",E$113:E$176) -> 17 | F5: =SUMIF($D$113:$D$176,"訪問",F$113:F$176) -> 16 | G5: =SUMIF($D$113:$D$176,"訪問",G$113:G$176) -> 14 | H5: =SUMIF($D$113:$D$176,"訪問",H$113:H$176) -> 18 | I5: =SUMIF($D$113:$D$176,"訪問",I$113:I$176) -> 14 | J5: =SUMIF($D$113:$D$176,"訪問",J$113:J$176) -> 12 | K5: =SUMIF($D$113:$D$176,"訪問",K$113:K$176) -> 9 | L5: =SUMIF($D$113:$D$176,"訪問",L$113:L$176) -> 16 | ... AI5: =SUMIF($D$113:$D$176,"訪問",AI$113:AI$176) -> 14 | AJ5: =SUM(OFFSET($E5,0,0,1,【設定】基本情報!$B$4)) -> 452 | AK5: =SUM(OFFSET($E6,0,0,1,【設定】基本情報!$B$4)) -> 452
D6: 訪介 | E6: =SUMIFS(E$113:E$176,$D$113:$D$176,"訪問",$AK$113:$AK$176,1) -> 17 | F6: =SUMIFS(F$113:F$176,$D$113:$D$176,"訪問",$AK$113:$AK$176,1) -> 16 | G6: =SUMIFS(G$113:G$176,$D$113:$D$176,"訪問",$AK$113:$AK$176,1) -> 14 | H6: =SUMIFS(H$113:H$176,$D$113:$D$176,"訪問",$AK$113:$AK$176,1) -> 18 | I6: =SUMIFS(I$113:I$176,$D$113:$D$176,"訪問",$AK$113:$AK$176,1) -> 14 | J6: =SUMIFS(J$113:J$176,$D$113:$D$176,"訪問",$AK$113:$AK$176,1) -> 12 | K6: =SUMIFS(K$113:K$176,$D$113:$D$176,"訪問",$AK$113:$AK$176,1) -> 9 | L6: =SUMIFS(L$113:L$176,$D$113:$D$176,"訪問",$AK$113:$AK$176,1) -> 16 | ... AI6: =SUMIFS(AI$113:AI$176,$D$113:$D$176,"訪問",$AK$113:$AK$176,1) -> 14
A7: =B7 -> 青砥 美秋 | B7: =IF(ISBLANK(【入力】利用者台帳!C3),"",【入力】利用者台帳!C3) -> 青砥 美秋 | C7: =IF(ISBLANK(【入力】利用者台帳!D3),"",【入力】利用者台帳!D3) | D7: 通泊 | F7: 1 | H7: 1 | J7: 1 | M7: 1 | O7: 1 | Q7: 1 | T7: 1 | V7: 1 | X7: 1 | AA7: 1 | AC7: 1 | AE7: 1 | AH7: 1 | AJ7: 火木土 体操の日は月曜希望２．４？
B8: =IF(ISBLANK(【入力】利用者台帳!C3),"",【入力】利用者台帳!C3) -> 青砥 美秋 | C8: =IF(ISBLANK(【入力】利用者台帳!D3),"",【入力】利用者台帳!D3) | D8: 訪問
A9: =B9 -> 安藤 敏子 | B9: =IF(ISBLANK(【入力】利用者台帳!C4),"",【入力】利用者台帳!C4) -> 安藤 敏子 | C9: =IF(ISBLANK(【入力】利用者台帳!D4),"",【入力】利用者台帳!D4) -> 要介護5 | D9: 通泊 | E9: 退所 | F9: 入所 | H9: 退所 | J9: 入所 | L9: 退所 | M9: 入所 | O9: 退所 | Q9: 入所 | S9: 退所 | T9: 入所 | V9: 退所 | X9: 入所 | Z9: 退所 | AA9: 入所 | AC9: 退所 | AE9: 入所 | AG9: 退所 | AH9: 入所 | AJ9: 2泊3日＋2泊3日 変更可
B10: =IF(ISBLANK(【入力】利用者台帳!C4),"",【入力】利用者台帳!C4) -> 安藤 敏子 | C10: =IF(ISBLANK(【入力】利用者台帳!D4),"",【入力】利用者台帳!D4) -> 要介護5 | D10: 訪問 | F10: 1 | J10: 1 | M10: 1 | Q10: 1 | T10: 1 | X10: 1 | AA10: 1 | AE10: 1 | AH10: 1
A11: =B11 -> 石井 さち子 | B11: =IF(ISBLANK(【入力】利用者台帳!C5),"",【入力】利用者台帳!C5) -> 石井 さち子 | C11: =IF(ISBLANK(【入力】利用者台帳!D5),"",【入力】利用者台帳!D5) -> 要介護3 | D11: 通泊 | E11: 1 | F11: 入所 | I11: 退所 | J11: 1 | L11: 1 | M11: 1 | N11: 1 | O11: 1 | P11: 1 | Q11: 1 | S11: 入所 | W11: 退所 | X11: 1 | Z11: 1 | AA11: 1 | AB11: 1 | AC11: 1 | AD11: 1 | AE11: 1 | AG11: 1 | AH11: 1 | AI11: 1 | AJ11: 日曜休み 朝9：40～10、20時迎え 土曜は10時～半の間。木曜２回は11時(訪診)
B12: =IF(ISBLANK(【入力】利用者台帳!C5),"",【入力】利用者台帳!C5) -> 石井 さち子 | C12: =IF(ISBLANK(【入力】利用者台帳!D5),"",【入力】利用者台帳!D5) -> 要介護3 | D12: 訪問
A13: =B13 -> 石橋 冨士代 | B13: =IF(ISBLANK(【入力】利用者台帳!C6),"",【入力】利用者台帳!C6) -> 石橋 冨士代 | C13: =IF(ISBLANK(【入力】利用者台帳!D6),"",【入力】利用者台帳!D6) -> 要介護1 | D13: 通泊 | G13: 1 | I13: 1 | J13: 1 | K13: 1 | M13: 1 | P13: 1 | Q13: 1 | R13: 1 | T13: 1 | W13: 1 | X13: 1 | Y13: 1 | AA13: 1 | AB13: 1 | AD13: 1 | AF13: 1 | AH13: 1 | AI13: 1 | AJ13: 木曜リハ16時～
B14: =IF(ISBLANK(【入力】利用者台帳!C6),"",【入力】利用者台帳!C6) -> 石橋 冨士代 | C14: =IF(ISBLANK(【入力】利用者台帳!D6),"",【入力】利用者台帳!D6) -> 要介護1 | D14: 訪問
A15: =B15 -> 伊藤 シゲ | B15: =IF(ISBLANK(【入力】利用者台帳!C7),"",【入力】利用者台帳!C7) -> 伊藤 シゲ | C15: =IF(ISBLANK(【入力】利用者台帳!D7),"",【入力】利用者台帳!D7) -> 要介護3 | D15: 通泊 | P15: 退所 | R15: 入所 | AD15: 退所 | AF15: 入所 | AJ15: ９：００まで 16:30以降、１７：００以降が良い
B16: =IF(ISBLANK(【入力】利用者台帳!C7),"",【入力】利用者台帳!C7) -> 伊藤 シゲ | C16: =IF(ISBLANK(【入力】利用者台帳!D7),"",【入力】利用者台帳!D7) -> 要介護3 | D16: 訪問 | P16: 1 | AD16: 1 | AJ16: 日曜は10時前後希望
A17: =B17 -> 伊藤 ミツ | B17: =IF(ISBLANK(【入力】利用者台帳!C8),"",【入力】利用者台帳!C8) -> 伊藤 ミツ | C17: =IF(ISBLANK(【入力】利用者台帳!D8),"",【入力】利用者台帳!D8) -> 要介護3 | D17: 通泊 | F17: 1 | H17: 1 | J17: 入所 | K17: 退所 | M17: 1 | O17: 1 | Q17: 入所 | R17: 退所 | T17: 1 | V17: 1 | X17: 入所 | Y17: 退所 | AA17: 1 | AC17: 1 | AE17: 入所 | AF17: 退所 | AH17: 1 | AJ17: 月曜訪問看護,週１程宿泊希望
B18: =IF(ISBLANK(【入力】利用者台帳!C8),"",【入力】利用者台帳!C8) -> 伊藤 ミツ | C18: =IF(ISBLANK(【入力】利用者台帳!D8),"",【入力】利用者台帳!D8) -> 要介護3 | D18: 訪問 | F18: 2 | G18: 1 | H18: 2 | I18: 1 | J18: 1 | K18: 1 | M18: 2 | N18: 1 | O18: 2 | P18: 1 | Q18: 1 | R18: 1 | T18: 2 | U18: 1 | V18: 2 | W18: 1 | X18: 1 | Y18: 1 | AA18: 2 | AB18: 1 | AC18: 2 | AD18: 1 | AE18: 1 | AF18: 1 | AH18: 2 | AI18: 1 | AJ18: ※年末年始以外は祝日訪看護有
A19: =B19 -> 岩永 里子 | B19: =IF(ISBLANK(【入力】利用者台帳!C9),"",【入力】利用者台帳!C9) -> 岩永 里子 | C19: =IF(ISBLANK(【入力】利用者台帳!D9),"",【入力】利用者台帳!D9) -> 要介護3 | D19: 通泊 | E19: 1 | G19: 1 | I19: 1 | L19: 1 | N19: 1 | P19: 1 | S19: 1 | U19: 1 | W19: 1 | Z19: 1 | AB19: 1 | AD19: 1 | AG19: 1 | AI19: 入所 | AJ19: 通所：月木＋家族要望
B20: =IF(ISBLANK(【入力】利用者台帳!C9),"",【入力】利用者台帳!C9) -> 岩永 里子 | C20: =IF(ISBLANK(【入力】利用者台帳!D9),"",【入力】利用者台帳!D9) -> 要介護3 | D20: 訪問 | E20: 2 | F20: 1 | G20: 2 | H20: 1 | I20: 2 | L20: 2 | M20: 1 | N20: 2 | O20: 1 | P20: 2 | S20: 2 | T20: 1 | U20: 2 | V20: 1 | W20: 2 | Z20: 2 | AA20: 1 | AB20: 2 | AC20: 1 | AD20: 2 | AG20: 2 | AH20: 1 | AI20: 1 | AJ20: 朝：９時台 夕：１７時前後 隣に行ってしまう
A21: =B21 -> 川原 克子 | B21: =IF(ISBLANK(【入力】利用者台帳!C10),"",【入力】利用者台帳!C10) -> 川原 克子 | C21: =IF(ISBLANK(【入力】利用者台帳!D10),"",【入力】利用者台帳!D10) -> 要介護4 | D21: 通泊 | E21: 入所 | F21: 退所 | G21: 入所 | H21: 退所 | I21: 入所 | J21: 退所 | K21: 入所 | O21: 退所 | S21: 1 | U21: 1 | X21: 1 | Z21: 1 | AB21: 1 | AE21: 1 | AG21: 1 | AJ21: 月水土 家族公演時にほぼ毎日利用
B22: =IF(ISBLANK(【入力】利用者台帳!C10),"",【入力】利用者台帳!C10) -> 川原 克子 | C22: =IF(ISBLANK(【入力】利用者台帳!D10),"",【入力】利用者台帳!D10) -> 要介護4 | D22: 訪問
A23: =B23 -> 工藤 信代 | B23: =IF(ISBLANK(【入力】利用者台帳!C11),"",【入力】利用者台帳!C11) -> 工藤 信代 | C23: =IF(ISBLANK(【入力】利用者台帳!D11),"",【入力】利用者台帳!D11) -> 要介護2 | D23: 通泊 | E23: 退所 | F23: 1 | H23: 1 | J23: 入所 | L23: 退所 | M23: 1 | O23: 1 | S23: 1 | T23: 1 | V23: 1 | X23: 入所 | Z23: 退所 | AA23: 1 | AC23: 1 | AE23: 入所 | AG23: 退所 | AH23: 1 | AI23: 1 | AJ23: 火・木・土～月
B24: =IF(ISBLANK(【入力】利用者台帳!C11),"",【入力】利用者台帳!C11) -> 工藤 信代 | C24: =IF(ISBLANK(【入力】利用者台帳!D11),"",【入力】利用者台帳!D11) -> 要介護2 | D24: 訪問 | E24: 1 | F24: 2 | H24: 2 | J24: 1 | L24: 1 | M24: 2 | O24: 2 | S24: 2 | T24: 2 | V24: 2 | X24: 1 | Z24: 1 | AA24: 2 | AC24: 2 | AE24: 1 | AG24: 1 | AH24: 2 | AI24: 2
A25: =B25 -> 坂本 みつ子 | B25: =IF(ISBLANK(【入力】利用者台帳!C12),"",【入力】利用者台帳!C12) -> 坂本 みつ子 | C25: =IF(ISBLANK(【入力】利用者台帳!D12),"",【入力】利用者台帳!D12) -> 要介護1 | D25: 通泊 | G25: 1 | J25: 1 | N25: 1 | Q25: 1 | U25: 1 | X25: 1 | AB25: 1 | AE25: 1 | AI25: 1 | AJ25: 訪問：３
B26: =IF(ISBLANK(【入力】利用者台帳!C12),"",【入力】利用者台帳!C12) -> 坂本 みつ子 | C26: =IF(ISBLANK(【入力】利用者台帳!D12),"",【入力】利用者台帳!D12) -> 要介護1 | D26: 訪問 | E26: 3 | F26: 3 | G26: 3 | H26: 3 | I26: 3 | J26: 3 | K26: 3 | L26: 3 | M26: 3 | N26: 3 | O26: 3 | P26: 3 | Q26: 3 | R26: 3 | S26: 3 | T26: 3 | U26: 3 | V26: 3 | W26: 3 | X26: 3 | Y26: 3 | Z26: 3 | AA26: 3 | AB26: 3 | AC26: 3 | AD26: 3 | AE26: 3 | AF26: 3 | AG26: 3 | AH26: 3 | AI26: 3
A27: =B27 -> 佐々木敦子 | B27: =IF(ISBLANK(【入力】利用者台帳!C13),"",【入力】利用者台帳!C13) -> 佐々木敦子 | C27: =IF(ISBLANK(【入力】利用者台帳!D13),"",【入力】利用者台帳!D13) -> 要介護4 | D27: 通泊 | E27: 入所 | I27: 退所 | L27: 入所 | P27: 退所 | S27: 入所 | W27: 退所 | Z27: 入所 | AJ27: 月曜リハビリ９:２０－１０:００ 金曜１７：４５
B28: =IF(ISBLANK(【入力】利用者台帳!C13),"",【入力】利用者台帳!C13) -> 佐々木敦子 | C28: =IF(ISBLANK(【入力】利用者台帳!D13),"",【入力】利用者台帳!D13) -> 要介護4 | D28: 訪問 | E28: 1 | I28: 1 | L28: 1 | P28: 1 | S28: 1 | W28: 1 | Z28: 1 | AJ28: 第3金曜訪問診療AM帰宅？
A29: =B29 -> 澤井 節子 | B29: =IF(ISBLANK(【入力】利用者台帳!C14),"",【入力】利用者台帳!C14) -> 澤井 節子 | C29: =IF(ISBLANK(【入力】利用者台帳!D14),"",【入力】利用者台帳!D14) -> 要介護1 | D29: 通泊 | E29: 退所 | G29: 1 | I29: 1 | K29: 1 | N29: 1 | P29: 1 | R29: 入所 | S29: 退所 | U29: 1 | W29: 1 | Y29: 1 | AA29: 入所 | AB29: 退所 | AD29: 1 | AF29: 1 | AI29: 1 | AJ29: 月１火か木曜歯科
B30: =IF(ISBLANK(【入力】利用者台帳!C14),"",【入力】利用者台帳!C14) -> 澤井 節子 | C30: =IF(ISBLANK(【入力】利用者台帳!D14),"",【入力】利用者台帳!D14) -> 要介護1 | D30: 訪問 | AJ30: 通所３(土肥さんと同じ日欲しい) 月に１泊2回
A31: =B31 -> 澤登 佳子 | B31: =IF(ISBLANK(【入力】利用者台帳!C15),"",【入力】利用者台帳!C15) -> 澤登 佳子 | C31: =IF(ISBLANK(【入力】利用者台帳!D15),"",【入力】利用者台帳!D15) -> 要介護2 | D31: 通泊 | Q31: 退所 | S31: 入所 | X31: 退所 | Z31: 入所 | AE31: 退所 | AG31: 入所 | AJ31: 月～土
B32: =IF(ISBLANK(【入力】利用者台帳!C15),"",【入力】利用者台帳!C15) -> 澤登 佳子 | C32: =IF(ISBLANK(【入力】利用者台帳!D15),"",【入力】利用者台帳!D15) -> 要介護2 | D32: 訪問 | Q32: 1 | S32: 1 | X32: 1 | Z32: 1 | AE32: 1 | AG32: 1
A33: =B33 -> 白井 加都子 | B33: =IF(ISBLANK(【入力】利用者台帳!C16),"",【入力】利用者台帳!C16) -> 白井 加都子 | C33: =IF(ISBLANK(【入力】利用者台帳!D16),"",【入力】利用者台帳!D16) -> 要介護1 | D33: 通泊 | E33: 1 | F33: 1 | G33: 1 | H33: 1 | I33: 1 | J33: 1 | L33: 1 | M33: 1 | N33: 1 | O33: 1 | P33: 1 | Q33: 1 | S33: 1 | T33: 1 | U33: 1 | V33: 1 | W33: 1 | X33: 1 | Z33: 1 | AA33: 1 | AB33: 1 | AC33: 1 | AD33: 1 | AE33: 1 | AG33: 1 | AH33: 1 | AJ33: 通所：月水金(土) 訪問：火木(土)
B34: =IF(ISBLANK(【入力】利用者台帳!C16),"",【入力】利用者台帳!C16) -> 白井 加都子 | C34: =IF(ISBLANK(【入力】利用者台帳!D16),"",【入力】利用者台帳!D16) -> 要介護1 | D34: 訪問 | E34: 2 | F34: 2 | G34: 2 | H34: 2 | I34: 2 | J34: 2 | L34: 2 | M34: 2 | N34: 2 | O34: 2 | P34: 2 | Q34: 2 | S34: 2 | T34: 2 | U34: 2 | V34: 2 | W34: 2 | X34: 2 | Z34: 2 | AA34: 2 | AB34: 2 | AC34: 2 | AD34: 2 | AE34: 2 | AG34: 2 | AH34: 2 | AJ34: 夏季のみ火木も通所
A35: =B35 -> 鈴木 育代 | B35: =IF(ISBLANK(【入力】利用者台帳!C17),"",【入力】利用者台帳!C17) -> 鈴木 育代 | C35: =IF(ISBLANK(【入力】利用者台帳!D17),"",【入力】利用者台帳!D17) -> 要介護4 | D35: 通泊 | E35: 入所 | I35: 退所 | L35: 入所 | P35: 退所 | S35: 入所 | W35: 退所 | Z35: 入所 | AD35: 退所 | AG35: 入所 | AJ35: 月：14時頃～金：18:00
B36: =IF(ISBLANK(【入力】利用者台帳!C17),"",【入力】利用者台帳!C17) -> 鈴木 育代 | C36: =IF(ISBLANK(【入力】利用者台帳!D17),"",【入力】利用者台帳!D17) -> 要介護4 | D36: 訪問 | E36: 1 | L36: 1 | S36: 1 | Z36: 1 | AG36: 1
A37: =B37 -> 高久 直美 | B37: =IF(ISBLANK(【入力】利用者台帳!C18),"",【入力】利用者台帳!C18) -> 高久 直美 | C37: =IF(ISBLANK(【入力】利用者台帳!D18),"",【入力】利用者台帳!D18) -> 要介護2 | D37: 通泊 | E37: 1 | F37: 1 | G37: 1 | H37: 1 | I37: 1 | J37: 1 | K37: 1 | L37: 1 | M37: 1 | N37: 1 | O37: 1 | P37: 1 | Q37: 1 | R37: 1 | S37: 1 | T37: 1 | U37: 1 | V37: 1 | W37: 1 | X37: 1 | Y37: 1 | Z37: 1 | AA37: 1 | AB37: 1 | AC37: 1 | AD37: 1 | AE37: 1 | AF37: 1 | AG37: 1 | AH37: 1 | AI37: 1 | AJ37: 不定期利用
B38: =IF(ISBLANK(【入力】利用者台帳!C18),"",【入力】利用者台帳!C18) -> 高久 直美 | C38: =IF(ISBLANK(【入力】利用者台帳!D18),"",【入力】利用者台帳!D18) -> 要介護2 | D38: 訪問
A39: =B39 -> 高橋 ハツコ | B39: =IF(ISBLANK(【入力】利用者台帳!C19),"",【入力】利用者台帳!C19) -> 高橋 ハツコ | C39: =IF(ISBLANK(【入力】利用者台帳!D19),"",【入力】利用者台帳!D19) -> 要介護1 | D39: 通泊 | F39: 入所 | G39: 退所 | J39: 入所 | L39: 退所 | N39: 入所 | O39: 退所 | Q39: 入所 | R39: 退所 | T39: 入所 | U39: 退所 | X39: 入所 | Z39: 退所 | AB39: 入所 | AC39: 退所 | AE39: 入所 | AG39: 退所 | AI39: 入所 | AJ39: 第1,3木曜AM自宅訪問診療
B40: =IF(ISBLANK(【入力】利用者台帳!C19),"",【入力】利用者台帳!C19) -> 高橋 ハツコ | C40: =IF(ISBLANK(【入力】利用者台帳!D19),"",【入力】利用者台帳!D19) -> 要介護1 | D40: 訪問 | E40: 3 | F40: 1 | G40: 2 | H40: 3 | I40: 3 | J40: 1 | L40: 2 | M40: 3 | N40: 1 | O40: 2 | P40: 3 | Q40: 1 | R40: 2 | S40: 3 | T40: 1 | U40: 2 | V40: 3 | W40: 3 | X40: 1 | Z40: 2 | AA40: 3 | AB40: 1 | AC40: 2 | AD40: 3 | AE40: 1 | AG40: 2 | AH40: 3 | AI40: 1
...

Sheet 利用票もどき
C1: 1 | D1: 2 | E1: 3 | F1: 4
A2: 青木 | B2: 通い | C2: 0 | D2: 1 | E2: 0 | F2: 0 | G2: 1
B3: 訪問 | C3: 3 | D3: 1
B4: 泊り | C4: 1

Sheet 【入力・帳票】ベッド表
A1: 泊り予定 ご利用者 確認欄 | B1: 1 | C1: =IFERROR(INDEX($B$50:$B$78,MATCH($B1,C$50:C$78,0)),"") -> 安藤 | D1: =IFERROR(INDEX($B$50:$B$78,MATCH($B1,D$50:D$78,0)),"") -> 伊シ | E1: =IFERROR(INDEX($B$50:$B$78,MATCH($B1,E$50:E$78,0)),"") -> 安藤 | F1: =IFERROR(INDEX($B$50:$B$78,MATCH($B1,F$50:F$78,0)),"") -> 安藤 | G1: =IFERROR(INDEX($B$50:$B$78,MATCH($B1,G$50:G$78,0)),"") -> 石井 | H1: =IFERROR(INDEX($B$50:$B$78,MATCH($B1,H$50:H$78,0)),"") -> 伊シ | I1: =IFERROR(INDEX($B$50:$B$78,MATCH($B1,I$50:I$78,0)),"") -> 安藤 | J1: =IFERROR(INDEX($B$50:$B$78,MATCH($B1,J$50:J$78,0)),"") -> 安藤 | ... AH1: =IFERROR(INDEX($B$50:$B$78,MATCH($B1,AH$50:AH$78,0)),"") -> 安藤
B2: 2 | C2: =IFERROR(INDEX($B$50:$B$78,MATCH($B2,C$50:C$78,0)),"") -> 伊シ | D2: =IFERROR(INDEX($B$50:$B$78,MATCH($B2,D$50:D$78,0)),"") -> 川原 | E2: =IFERROR(INDEX($B$50:$B$78,MATCH($B2,E$50:E$78,0)),"") -> 石井 | F2: =IFERROR(INDEX($B$50:$B$78,MATCH($B2,F$50:F$78,0)),"") -> 石井 | G2: =IFERROR(INDEX($B$50:$B$78,MATCH($B2,G$50:G$78,0)),"") -> 伊シ | H2: =IFERROR(INDEX($B$50:$B$78,MATCH($B2,H$50:H$78,0)),"") -> 川原 | I2: =IFERROR(INDEX($B$50:$B$78,MATCH($B2,I$50:I$78,0)),"") -> 伊シ | J2: =IFERROR(INDEX($B$50:$B$78,MATCH($B2,J$50:J$78,0)),"") -> 伊シ | ... AH2: =IFERROR(INDEX($B$50:$B$78,MATCH($B2,AH$50:AH$78,0)),"") -> 伊シ
B3: 3 | C3: =IFERROR(INDEX($B$50:$B$78,MATCH($B3,C$50:C$78,0)),"") -> 工藤 | D3: =IFERROR(INDEX($B$50:$B$78,MATCH($B3,D$50:D$78,0)),"") -> 佐々 | E3: =IFERROR(INDEX($B$50:$B$78,MATCH($B3,E$50:E$78,0)),"") -> 伊シ | F3: =IFERROR(INDEX($B$50:$B$78,MATCH($B3,F$50:F$78,0)),"") -> 伊シ | G3: =IFERROR(INDEX($B$50:$B$78,MATCH($B3,G$50:G$78,0)),"") -> 佐々 | H3: =IFERROR(INDEX($B$50:$B$78,MATCH($B3,H$50:H$78,0)),"") -> 澤登 | I3: =IFERROR(INDEX($B$50:$B$78,MATCH($B3,I$50:I$78,0)),"") -> 伊ミ | J3: =IFERROR(INDEX($B$50:$B$78,MATCH($B3,J$50:J$78,0)),"") -> 川原 | ... AH3: =IFERROR(INDEX($B$50:$B$78,MATCH($B3,AH$50:AH$78,0)),"") -> 岩永
B4: 4 | C4: =IFERROR(INDEX($B$50:$B$78,MATCH($B4,C$50:C$78,0)),"") -> 澤井 | D4: =IFERROR(INDEX($B$50:$B$78,MATCH($B4,D$50:D$78,0)),"") -> 澤登 | E4: =IFERROR(INDEX($B$50:$B$78,MATCH($B4,E$50:E$78,0)),"") -> 佐々 | F4: =IFERROR(INDEX($B$50:$B$78,MATCH($B4,F$50:F$78,0)),"") -> 川原 | G4: =IFERROR(INDEX($B$50:$B$78,MATCH($B4,G$50:G$78,0)),"") -> 澤登 | H4: =IFERROR(INDEX($B$50:$B$78,MATCH($B4,H$50:H$78,0)),"") -> 仲里 | I4: =IFERROR(INDEX($B$50:$B$78,MATCH($B4,I$50:I$78,0)),"") -> 工藤 | J4: =IFERROR(INDEX($B$50:$B$78,MATCH($B4,J$50:J$78,0)),"") -> 工藤 | ... AH4: =IFERROR(INDEX($B$50:$B$78,MATCH($B4,AH$50:AH$78,0)),"") -> 佐々
B5: 5 | C5: =IFERROR(INDEX($B$50:$B$78,MATCH($B5,C$50:C$78,0)),"") -> 澤登 | D5: =IFERROR(INDEX($B$50:$B$78,MATCH($B5,D$50:D$78,0)),"") -> 鈴木 | E5: =IFERROR(INDEX($B$50:$B$78,MATCH($B5,E$50:E$78,0)),"") -> 澤登 | F5: =IFERROR(INDEX($B$50:$B$78,MATCH($B5,F$50:F$78,0)),"") -> 佐々 | G5: =IFERROR(INDEX($B$50:$B$78,MATCH($B5,G$50:G$78,0)),"") -> 鈴木 | H5: =IFERROR(INDEX($B$50:$B$78,MATCH($B5,H$50:H$78,0)),"") -> 二宮 | I5: =IFERROR(INDEX($B$50:$B$78,MATCH($B5,I$50:I$78,0)),"") -> 澤登 | J5: =IFERROR(INDEX($B$50:$B$78,MATCH($B5,J$50:J$78,0)),"") -> 澤登 | ... AH5: =IFERROR(INDEX($B$50:$B$78,MATCH($B5,AH$50:AH$78,0)),"") -> 澤登
B6: 6 | C6: =IFERROR(INDEX($B$50:$B$78,MATCH($B6,C$50:C$78,0)),"") -> 仲里 | D6: =IFERROR(INDEX($B$50:$B$78,MATCH($B6,D$50:D$78,0)),"") -> 星野 | E6: =IFERROR(INDEX($B$50:$B$78,MATCH($B6,E$50:E$78,0)),"") -> 鈴木 | F6: =IFERROR(INDEX($B$50:$B$78,MATCH($B6,F$50:F$78,0)),"") -> 澤登 | G6: =IFERROR(INDEX($B$50:$B$78,MATCH($B6,G$50:G$78,0)),"") -> 仲里 | H6: =IFERROR(INDEX($B$50:$B$78,MATCH($B6,H$50:H$78,0)),"") -> 星野 | I6: =IFERROR(INDEX($B$50:$B$78,MATCH($B6,I$50:I$78,0)),"") -> 高橋 | J6: =IFERROR(INDEX($B$50:$B$78,MATCH($B6,J$50:J$78,0)),"") -> 高橋 | ... AH6: =IFERROR(INDEX($B$50:$B$78,MATCH($B6,AH$50:AH$78,0)),"") -> 鈴木
B7: 7 | C7: =IFERROR(INDEX($B$50:$B$78,MATCH($B7,C$50:C$78,0)),"") -> 二宮 | D7: =IFERROR(INDEX($B$50:$B$78,MATCH($B7,D$50:D$78,0)),"") -> 山地 | E7: =IFERROR(INDEX($B$50:$B$78,MATCH($B7,E$50:E$78,0)),"") -> 高橋 | F7: =IFERROR(INDEX($B$50:$B$78,MATCH($B7,F$50:F$78,0)),"") -> 鈴木 | G7: =IFERROR(INDEX($B$50:$B$78,MATCH($B7,G$50:G$78,0)),"") -> 星野 | H7: =IFERROR(INDEX($B$50:$B$78,MATCH($B7,H$50:H$78,0)),"") -> 山地 | I7: =IFERROR(INDEX($B$50:$B$78,MATCH($B7,I$50:I$78,0)),"") -> 仲里 | J7: =IFERROR(INDEX($B$50:$B$78,MATCH($B7,J$50:J$78,0)),"") -> 仲里 | ... AH7: =IFERROR(INDEX($B$50:$B$78,MATCH($B7,AH$50:AH$78,0)),"") -> 高橋
B8: 8 | C8: =IFERROR(INDEX($B$50:$B$78,MATCH($B8,C$50:C$78,0)),"") -> 星野 | D8: =IFERROR(INDEX($B$50:$B$78,MATCH($B8,D$50:D$78,0)),"") -> 山本 | E8: =IFERROR(INDEX($B$50:$B$78,MATCH($B8,E$50:E$78,0)),"") -> 星野 | F8: =IFERROR(INDEX($B$50:$B$78,MATCH($B8,F$50:F$78,0)),"") -> 星野 | G8: =IFERROR(INDEX($B$50:$B$78,MATCH($B8,G$50:G$78,0)),"") -> 山地 | H8: =IFERROR(INDEX($B$50:$B$78,MATCH($B8,H$50:H$78,0)),"") -> 吉田 | I8: =IFERROR(INDEX($B$50:$B$78,MATCH($B8,I$50:I$78,0)),"") -> 二宮 | J8: =IFERROR(INDEX($B$50:$B$78,MATCH($B8,J$50:J$78,0)),"") -> 二宮 | ... AH8: =IFERROR(INDEX($B$50:$B$78,MATCH($B8,AH$50:AH$78,0)),"") -> 渡邊
B9: 9 | C9: =IFERROR(INDEX($B$50:$B$78,MATCH($B9,C$50:C$78,0)),"") -> 吉田 | D9: =IFERROR(INDEX($B$50:$B$78,MATCH($B9,D$50:D$78,0)),"") -> 渡邊 | E9: =IFERROR(INDEX($B$50:$B$78,MATCH($B9,E$50:E$78,0)),"") -> 山本 | F9: =IFERROR(INDEX($B$50:$B$78,MATCH($B9,F$50:F$78,0)),"") -> 山本 | G9: =IFERROR(INDEX($B$50:$B$78,MATCH($B9,G$50:G$78,0)),"") -> 渡邊 | H9: =IFERROR(INDEX($B$50:$B$78,MATCH($B9,H$50:H$78,0)),"") -> 渡邊 | I9: =IFERROR(INDEX($B$50:$B$78,MATCH($B9,I$50:I$78,0)),"") -> 星野 | J9: =IFERROR(INDEX($B$50:$B$78,MATCH($B9,J$50:J$78,0)),"") -> 星野 | ... AH9: =IFERROR(INDEX($B$50:$B$78,MATCH($B9,AH$50:AH$78,0)),"")
C10: =D10-1 -> 45991 | D10: =【入力】調整表!$E$1 -> 45992 | E10: =D10+1 -> 45993 | F10: =E10+1 -> 45994 | G10: =F10+1 -> 45995 | H10: =G10+1 -> 45996 | I10: =H10+1 -> 45997 | J10: =I10+1 -> 45998 | K10: =J10+1 -> 45999 | L10: =K10+1 -> 46000 | ... AH10: =AG10+1 -> 46022
C11: =C10 -> 45991 | D11: =D10 -> 45992 | E11: =E10 -> 45993 | F11: =F10 -> 45994 | G11: =G10 -> 45995 | H11: =H10 -> 45996 | I11: =I10 -> 45997 | J11: =J10 -> 45998 | ... AH11: =AH10 -> 46022
A12: ベッド表 割り当て | B12: 1 | C12: 星野 | D12: 星野 | E12: 星野 | F12: 鈴木 | G12: 鈴木 | H12: 鈴木 | I12: 鈴木 | J12: 星野 | K12: 星野 | L12: 星野 | M12: 鈴木 | N12: 鈴木 | O12: 鈴木 | P12: 鈴木 | Q12: 星野 | R12: 星野 | S12: 星野 | T12: 鈴木 | U12: 鈴木 | V12: 鈴木 | W12: 鈴木 | X12: 山地 | Y12: 高橋 | Z12: 高橋 | AA12: 鈴木 | AB12: 鈴木 | AC12: 鈴木 | AD12: 鈴木 | AF12: 高橋 | AG12: 澤井
B13: 2 | C13: 山地 | D13: 伊ミ | E13: 高橋 | F13: 渡邊 | G13: 渡邊 | H13: 渡邊 | I13: 渡邊 | J13: 渡邊 | K13: 川原 | L13: 川原 | M13: 渡邊 | N13: 渡邊 | O13: 渡邊 | P13: 渡邊 | Q13: 渡邊 | R13: 伊ミ | S13: 川原 | T13: 渡邊 | U13: 渡邊 | V13: 渡邊 | W13: 渡邊 | X13: 渡邊 | Y13: 伊ミ | Z13: 佐々 | AA13: 渡邊 | AB13: 渡邊 | AC13: 渡邊 | AD13: 渡邊 | AE13: 渡邊 | AF13: 伊ミ
B14: 3 | C14: 安藤 | D14: 安藤 | E14: 安藤 | F14: 山地 | G14: 高橋 | H14: 安藤 | I14: 安藤 | J14: 川原 | K14: 安藤 | L14: 安藤 | M14: 川原 | N14: 川原 | O14: 安藤 | P14: 山地 | Q14: 安藤 | R14: 安藤 | S14: 安藤 | T14: 山地 | U14: 安藤 | V14: 安藤 | W14: 川原 | X14: 川原 | Y14: 安藤 | Z14: 安藤 | AB14: 安藤 | AC14: 安藤 | AD14: 石井 | AE14: 石井 | AF14: 安藤 | AG14: 安藤
B15: 4 | C15: 工藤 | D15: 工藤 | E15: 工藤 | F15: 石井 | G15: 石井 | I15: 山地 | J15: 山地 | K15: 工藤 | L15: 工藤 | M15: 佐々 | N15: 佐々 | O15: 佐々 | P15: 佐々 | Q15: 山地 | R15: 工藤 | S15: 工藤 | T15: 川原 | U15: 川原 | V15: 川原 | W15: 石井 | X15: 石井 | Y15: 工藤 | Z15: 工藤 | AA15: 川原 | AB15: 川原 | AC15: 川原 | AD15: 川原 | AE15: 山地 | AF15: 工藤 | AG15: 工藤
B16: 5 | C16: 澤登 | E16: 澤井 | F16: 澤登 | G16: 澤登 | H16: 澤登 | I16: 澤登 | J16: 澤登 | K16: 高橋 | L16: 高橋 | M16: 澤登 | N16: 澤登 | O16: 澤登 | P16: 澤登 | Q16: 澤登 | R16: 高橋 | S16: 高橋 | T16: 澤登 | U16: 澤登 | V16: 澤登 | W16: 澤登 | X16: 澤登 | Y16: 川原 | Z16: 川原 | AA16: 澤登 | AB16: 澤登 | AC16: 澤登 | AD16: 澤登 | AE16: 澤登 | AF16: 澤登 | AG16: 澤登
B17: 6 | C17: 吉田 | D17: 吉田 | E17: 吉田 | F17: 佐々 | G17: 佐々 | H17: 佐々 | I17: 佐々 | J17: 吉田 | K17: 吉田 | L17: 吉田 | M17: 吉田 | N17: 吉田 | O17: 吉田 | P17: 吉田 | Q17: 吉田 | R17: 吉田 | S17: 吉田 | T17: 佐々 | U17: 佐々 | V17: 佐々 | W17: 佐々 | X17: 吉田 | Y17: 吉田 | Z17: 吉田 | AA17: 佐々 | AB17: 佐々 | AC17: 佐々 | AD17: 佐々 | AE17: 吉田 | AF17: 吉田 | AG17: 吉田
B18: 7 | C18: 仲里 | D18: 仲里 | E18: 仲里 | F18: 山本 | G18: 山本 | H18: 山本 | I18: 仲里 | J18: 仲里 | K18: 仲里 | L18: 仲里 | M18: 山地 | N18: 山本 | O18: 山本 | P18: 仲里 | Q18: 仲里 | R18: 仲里 | S18: 仲里 | T18: 山本 | U18: 山本 | V18: 山本 | W18: 仲里 | X18: 仲里 | Y18: 仲里 | Z18: 仲里 | AA18: 山本 | AB18: 山本 | AC18: 山本 | AD18: 仲里 | AE18: 仲里 | AF18: 仲里 | AG18: 仲里
B19: 8 | C19: 二宮 | D19: 二宮 | E19: 二宮 | F19: 星野 | G19: 星野 | H19: 星野 | I19: 星野 | J19: 二宮 | K19: 二宮 | L19: 二宮 | M19: 星野 | N19: 星野 | O19: 星野 | P19: 星野 | Q19: 二宮 | R19: 二宮 | S19: 二宮 | T19: 星野 | U19: 星野 | V19: 星野 | W19: 山地 | X19: 二宮 | Y19: 二宮 | Z19: 二宮 | AA19: 山地 | AC19: 高橋 | AD19: 山地 | AE19: 二宮 | AF19: 二宮 | AG19: 二宮
B20: 9 | C20: 川原 | D20: 高橋 | E20: 伊シ | F20: 伊シ | G20: 伊シ | H20: 伊シ | I20: 伊シ | J20: 伊シ | K20: 伊シ | L20: 伊シ | M20: 伊シ | N20: 伊シ | O20: 伊シ | P20: 伊シ | Q20: 川原 | R20: 川原 | S20: 伊シ | T20: 伊シ | U20: 伊シ | V20: 伊シ | W20: 伊シ | X20: 伊シ | Y20: 伊シ | Z20: 伊シ | AA20: 伊シ | AB20: 伊シ | AC20: 伊シ | AD20: 伊シ | AF20: 川原 | AG20: 伊シ
A23: 小規模多機能ベッド表
A24: =D10 -> 45992 | D24: =D10 -> 45992 | E24: =E10 -> 45993 | F24: =F10 -> 45994 | G24: =G10 -> 45995 | H24: =H10 -> 45996 | I24: =I10 -> 45997 | J24: =J10 -> 45998 | K24: =K10 -> 45999 | ... AH24: =AH10 -> 46022
D25: =D11 -> 45992 | E25: =E11 -> 45993 | F25: =F11 -> 45994 | G25: =G11 -> 45995 | H25: =H11 -> 45996 | I25: =I11 -> 45997 | J25: =J11 -> 45998 | K25: =K11 -> 45999 | ... AH25: =AH11 -> 46022
A26: 1号室 | D26: =IF(IFERROR(INDEX($D$83:$AH$111,MATCH(C12,$B$83:$B$111,0),D$49-1),0)=退所日,C12,IF(IFERROR(INDEX($D$83:$AH$111,MATCH(D12,$B$83:$B$111,0),D$49-1),0)=連泊日,D12,"")) -> 星野 | E26: =IF(IFERROR(INDEX($D$83:$AH$111,MATCH(D12,$B$83:$B$111,0),E$49-1),0)=退所日,D12,IF(IFERROR(INDEX($D$83:$AH$111,MATCH(E12,$B$83:$B$111,0),E$49-1),0)=連泊日,E12,"")) -> 星野 | F26: =IF(IFERROR(INDEX($D$83:$AH$111,MATCH(E12,$B$83:$B$111,0),F$49-1),0)=退所日,E12,IF(IFERROR(INDEX($D$83:$AH$111,MATCH(F12,$B$83:$B$111,0),F$49-1),0)=連泊日,F12,"")) -> 鈴木 | G26: =IF(IFERROR(INDEX($D$83:$AH$111,MATCH(F12,$B$83:$B$111,0),G$49-1),0)=退所日,F12,IF(IFERROR(INDEX($D$83:$AH$111,MATCH(G12,$B$83:$B$111,0),G$49-1),0)=連泊日,G12,"")) -> 鈴木 | H26: =IF(IFERROR(INDEX($D$83:$AH$111,MATCH(G12,$B$83:$B$111,0),H$49-1),0)=退所日,G12,IF(IFERROR(INDEX($D$83:$AH$111,MATCH(H12,$B$83:$B$111,0),H$49-1),0)=連泊日,H12,"")) -> 鈴木 | I26: =IF(IFERROR(INDEX($D$83:$AH$111,MATCH(H12,$B$83:$B$111,0),I$49-1),0)=退所日,H12,IF(IFERROR(INDEX($D$83:$AH$111,MATCH(I12,$B$83:$B$111,0),I$49-1),0)=連泊日,I12,"")) | J26: =IF(IFERROR(INDEX($D$83:$AH$111,MATCH(I12,$B$83:$B$111,0),J$49-1),0)=退所日,I12,IF(IFERROR(INDEX($D$83:$AH$111,MATCH(J12,$B$83:$B$111,0),J$49-1),0)=連泊日,J12,"")) -> 星野 | K26: =IF(IFERROR(INDEX($D$83:$AH$111,MATCH(J12,$B$83:$B$111,0),K$49-1),0)=退所日,J12,IF(IFERROR(INDEX($D$83:$AH$111,MATCH(K12,$B$83:$B$111,0),K$49-1),0)=連泊日,K12,"")) -> 星野 | ... AH26: =IF(IFERROR(INDEX($D$83:$AH$111,MATCH(AG12,$B$83:$B$111,0),AH$49-1),0)=退所日,AG12,IF(IFERROR(INDEX($D$83:$AH$111,MATCH(AH12,$B$83:$B$111,0),AH$49-1),0)=連泊日,AH12,""))
D27: =IF(ISBLANK(D12),"",IF(OR(INDEX($D$83:$AH$111,MATCH(D12,$B$83:$B$111,0),D$49-1)={11,12}),D12,"")) -> 星野 | E27: =IF(ISBLANK(E12),"",IF(OR(INDEX($D$83:$AH$111,MATCH(E12,$B$83:$B$111,0),E$49-1)={11,12}),E12,"")) -> 星野 | F27: =IF(ISBLANK(F12),"",IF(OR(INDEX($D$83:$AH$111,MATCH(F12,$B$83:$B$111,0),F$49-1)={11,12}),F12,"")) -> 鈴木 | G27: =IF(ISBLANK(G12),"",IF(OR(INDEX($D$83:$AH$111,MATCH(G12,$B$83:$B$111,0),G$49-1)={11,12}),G12,"")) -> 鈴木 | H27: =IF(ISBLANK(H12),"",IF(OR(INDEX($D$83:$AH$111,MATCH(H12,$B$83:$B$111,0),H$49-1)={11,12}),H12,"")) | I27: =IF(ISBLANK(I12),"",IF(OR(INDEX($D$83:$AH$111,MATCH(I12,$B$83:$B$111,0),I$49-1)={11,12}),I12,"")) | J27: =IF(ISBLANK(J12),"",IF(OR(INDEX($D$83:$AH$111,MATCH(J12,$B$83:$B$111,0),J$49-1)={11,12}),J12,"")) -> 星野 | K27: =IF(ISBLANK(K12),"",IF(OR(INDEX($D$83:$AH$111,MATCH(K12,$B$83:$B$111,0),K$49-1)={11,12}),K12,"")) -> 星野 | ... AH27: =IF(ISBLANK(AH12),"",IF(OR(INDEX($D$83:$AH$111,MATCH(AH12,$B$83:$B$111,0),AH$49-1)={11,12}),AH12,""))
A28: 2号室 | D28: =IF(IFERROR(INDEX($D$83:$AH$111,MATCH(C13,$B$83:$B$111,0),D$49-1),0)=退所日,C13,IF(IFERROR(INDEX($D$83:$AH$111,MATCH(D13,$B$83:$B$111,0),D$49-1),0)=連泊日,D13,"")) | E28: =IF(IFERROR(INDEX($D$83:$AH$111,MATCH(D13,$B$83:$B$111,0),E$49-1),0)=退所日,D13,IF(IFERROR(INDEX($D$83:$AH$111,MATCH(E13,$B$83:$B$111,0),E$49-1),0)=連泊日,E13,"")) | F28: =IF(IFERROR(INDEX($D$83:$AH$111,MATCH(E13,$B$83:$B$111,0),F$49-1),0)=退所日,E13,IF(IFERROR(INDEX($D$83:$AH$111,MATCH(F13,$B$83:$B$111,0),F$49-1),0)=連泊日,F13,"")) -> 高橋 | G28: =IF(IFERROR(INDEX($D$83:$AH$111,MATCH(F13,$B$83:$B$111,0),G$49-1),0)=退所日,F13,IF(IFERROR(INDEX($D$83:$AH$111,MATCH(G13,$B$83:$B$111,0),G$49-1),0)=連泊日,G13,"")) -> 渡邊 | H28: =IF(IFERROR(INDEX($D$83:$AH$111,MATCH(G13,$B$83:$B$111,0),H$49-1),0)=退所日,G13,IF(IFERROR(INDEX($D$83:$AH$111,MATCH(H13,$B$83:$B$111,0),H$49-1),0)=連泊日,H13,"")) -> 渡邊 | I28: =IF(IFERROR(INDEX($D$83:$AH$111,MATCH(H13,$B$83:$B$111,0),I$49-1),0)=退所日,H13,IF(IFERROR(INDEX($D$83:$AH$111,MATCH(I13,$B$83:$B$111,0),I$49-1),0)=連泊日,I13,"")) -> 渡邊 | J28: =IF(IFERROR(INDEX($D$83:$AH$111,MATCH(I13,$B$83:$B$111,0),J$49-1),0)=退所日,I13,IF(IFERROR(INDEX($D$83:$AH$111,MATCH(J13,$B$83:$B$111,0),J$49-1),0)=連泊日,J13,"")) | K28: =IF(IFERROR(INDEX($D$83:$AH$111,MATCH(J13,$B$83:$B$111,0),K$49-1),0)=退所日,J13,IF(IFERROR(INDEX($D$83:$AH$111,MATCH(K13,$B$83:$B$111,0),K$49-1),0)=連泊日,K13,"")) -> 川原 | ... AH28: =IF(IFERROR(INDEX($D$83:$AH$111,MATCH(AG13,$B$83:$B$111,0),AH$49-1),0)=退所日,AG13,IF(IFERROR(INDEX($D$83:$AH$111,MATCH(AH13,$B$83:$B$111,0),AH$49-1),0)=連泊日,AH13,""))
D29: =IF(ISBLANK(D13),"",IF(OR(INDEX($D$83:$AH$111,MATCH(D13,$B$83:$B$111,0),D$49-1)={11,12}),D13,"")) | E29: =IF(ISBLANK(E13),"",IF(OR(INDEX($D$83:$AH$111,MATCH(E13,$B$83:$B$111,0),E$49-1)={11,12}),E13,"")) -> 高橋 | F29: =IF(ISBLANK(F13),"",IF(OR(INDEX($D$83:$AH$111,MATCH(F13,$B$83:$B$111,0),F$49-1)={11,12}),F13,"")) -> 渡邊 | G29: =IF(ISBLANK(G13),"",IF(OR(INDEX($D$83:$AH$111,MATCH(G13,$B$83:$B$111,0),G$49-1)={11,12}),G13,"")) -> 渡邊 | H29: =IF(ISBLANK(H13),"",IF(OR(INDEX($D$83:$AH$111,MATCH(H13,$B$83:$B$111,0),H$49-1)={11,12}),H13,"")) -> 渡邊 | I29: =IF(ISBLANK(I13),"",IF(OR(INDEX($D$83:$AH$111,MATCH(I13,$B$83:$B$111,0),I$49-1)={11,12}),I13,"")) | J29: =IF(ISBLANK(J13),"",IF(OR(INDEX($D$83:$AH$111,MATCH(J13,$B$83:$B$111,0),J$49-1)={11,12}),J13,"")) | K29: =IF(ISBLANK(K13),"",IF(OR(INDEX($D$83:$AH$111,MATCH(K13,$B$83:$B$111,0),K$49-1)={11,12}),K13,"")) -> 川原 | ... AH29: =IF(ISBLANK(AH13),"",IF(OR(INDEX($D$83:$AH$111,MATCH(AH13,$B$83:$B$111,0),AH$49-1)={11,12}),AH13,""))
A30: 3号室 | D30: =IF(IFERROR(INDEX($D$83:$AH$111,MATCH(C14,$B$83:$B$111,0),D$49-1),0)=退所日,C14,IF(IFERROR(INDEX($D$83:$AH$111,MATCH(D14,$B$83:$B$111,0),D$49-1),0)=連泊日,D14,"")) -> 安藤 | E30: =IF(IFERROR(INDEX($D$83:$AH$111,MATCH(D14,$B$83:$B$111,0),E$49-1),0)=退所日,D14,IF(IFERROR(INDEX($D$83:$AH$111,MATCH(E14,$B$83:$B$111,0),E$49-1),0)=連泊日,E14,"")) | F30: =IF(IFERROR(INDEX($D$83:$AH$111,MATCH(E14,$B$83:$B$111,0),F$49-1),0)=退所日,E14,IF(IFERROR(INDEX($D$83:$AH$111,MATCH(F14,$B$83:$B$111,0),F$49-1),0)=連泊日,F14,"")) | G30: =IF(IFERROR(INDEX($D$83:$AH$111,MATCH(F14,$B$83:$B$111,0),G$49-1),0)=退所日,F14,IF(IFERROR(INDEX($D$83:$AH$111,MATCH(G14,$B$83:$B$111,0),G$49-1),0)=連泊日,G14,"")) | H30: =IF(IFERROR(INDEX($D$83:$AH$111,MATCH(G14,$B$83:$B$111,0),H$49-1),0)=退所日,G14,IF(IFERROR(INDEX($D$83:$AH$111,MATCH(H14,$B$83:$B$111,0),H$49-1),0)=連泊日,H14,"")) | I30: =IF(IFERROR(INDEX($D$83:$AH$111,MATCH(H14,$B$83:$B$111,0),I$49-1),0)=退所日,H14,IF(IFERROR(INDEX($D$83:$AH$111,MATCH(I14,$B$83:$B$111,0),I$49-1),0)=連泊日,I14,"")) | J30: =IF(IFERROR(INDEX($D$83:$AH$111,MATCH(I14,$B$83:$B$111,0),J$49-1),0)=退所日,I14,IF(IFERROR(INDEX($D$83:$AH$111,MATCH(J14,$B$83:$B$111,0),J$49-1),0)=連泊日,J14,"")) | K30: =IF(IFERROR(INDEX($D$83:$AH$111,MATCH(J14,$B$83:$B$111,0),K$49-1),0)=退所日,J14,IF(IFERROR(INDEX($D$83:$AH$111,MATCH(K14,$B$83:$B$111,0),K$49-1),0)=連泊日,K14,"")) | ... AH30: =IF(IFERROR(INDEX($D$83:$AH$111,MATCH(AG14,$B$83:$B$111,0),AH$49-1),0)=退所日,AG14,IF(IFERROR(INDEX($D$83:$AH$111,MATCH(AH14,$B$83:$B$111,0),AH$49-1),0)=連泊日,AH14,""))
D31: =IF(ISBLANK(D14),"",IF(OR(INDEX($D$83:$AH$111,MATCH(D14,$B$83:$B$111,0),D$49-1)={11,12}),D14,"")) | E31: =IF(ISBLANK(E14),"",IF(OR(INDEX($D$83:$AH$111,MATCH(E14,$B$83:$B$111,0),E$49-1)={11,12}),E14,"")) -> 安藤 | F31: =IF(ISBLANK(F14),"",IF(OR(INDEX($D$83:$AH$111,MATCH(F14,$B$83:$B$111,0),F$49-1)={11,12}),F14,"")) | G31: =IF(ISBLANK(G14),"",IF(OR(INDEX($D$83:$AH$111,MATCH(G14,$B$83:$B$111,0),G$49-1)={11,12}),G14,"")) | H31: =IF(ISBLANK(H14),"",IF(OR(INDEX($D$83:$AH$111,MATCH(H14,$B$83:$B$111,0),H$49-1)={11,12}),H14,"")) | I31: =IF(ISBLANK(I14),"",IF(OR(INDEX($D$83:$AH$111,MATCH(I14,$B$83:$B$111,0),I$49-1)={11,12}),I14,"")) -> 安藤 | J31: =IF(ISBLANK(J14),"",IF(OR(INDEX($D$83:$AH$111,MATCH(J14,$B$83:$B$111,0),J$49-1)={11,12}),J14,"")) -> 川原 | K31: =IF(ISBLANK(K14),"",IF(OR(INDEX($D$83:$AH$111,MATCH(K14,$B$83:$B$111,0),K$49-1)={11,12}),K14,"")) | ... AH31: =IF(ISBLANK(AH14),"",IF(OR(INDEX($D$83:$AH$111,MATCH(AH14,$B$83:$B$111,0),AH$49-1)={11,12}),AH14,""))
A32: 4号室 | D32: =IF(IFERROR(INDEX($D$83:$AH$111,MATCH(C15,$B$83:$B$111,0),D$49-1),0)=退所日,C15,IF(IFERROR(INDEX($D$83:$AH$111,MATCH(D15,$B$83:$B$111,0),D$49-1),0)=連泊日,D15,"")) -> 工藤 | E32: =IF(IFERROR(INDEX($D$83:$AH$111,MATCH(D15,$B$83:$B$111,0),E$49-1),0)=退所日,D15,IF(IFERROR(INDEX($D$83:$AH$111,MATCH(E15,$B$83:$B$111,0),E$49-1),0)=連泊日,E15,"")) | F32: =IF(IFERROR(INDEX($D$83:$AH$111,MATCH(E15,$B$83:$B$111,0),F$49-1),0)=退所日,E15,IF(IFERROR(INDEX($D$83:$AH$111,MATCH(F15,$B$83:$B$111,0),F$49-1),0)=連泊日,F15,"")) -> 石井 | G32: =IF(IFERROR(INDEX($D$83:$AH$111,MATCH(F15,$B$83:$B$111,0),G$49-1),0)=退所日,F15,IF(IFERROR(INDEX($D$83:$AH$111,MATCH(G15,$B$83:$B$111,0),G$49-1),0)=連泊日,G15,"")) -> 石井 | H32: =IF(IFERROR(INDEX($D$83:$AH$111,MATCH(G15,$B$83:$B$111,0),H$49-1),0)=退所日,G15,IF(IFERROR(INDEX($D$83:$AH$111,MATCH(H15,$B$83:$B$111,0),H$49-1),0)=連泊日,H15,"")) -> 石井 | I32: =IF(IFERROR(INDEX($D$83:$AH$111,MATCH(H15,$B$83:$B$111,0),I$49-1),0)=退所日,H15,IF(IFERROR(INDEX($D$83:$AH$111,MATCH(I15,$B$83:$B$111,0),I$49-1),0)=連泊日,I15,"")) | J32: =IF(IFERROR(INDEX($D$83:$AH$111,MATCH(I15,$B$83:$B$111,0),J$49-1),0)=退所日,I15,IF(IFERROR(INDEX($D$83:$AH$111,MATCH(J15,$B$83:$B$111,0),J$49-1),0)=連泊日,J15,"")) | K32: =IF(IFERROR(INDEX($D$83:$AH$111,MATCH(J15,$B$83:$B$111,0),K$49-1),0)=退所日,J15,IF(IFERROR(INDEX($D$83:$AH$111,MATCH(K15,$B$83:$B$111,0),K$49-1),0)=連泊日,K15,"")) | ... AH32: =IF(IFERROR(INDEX($D$83:$AH$111,MATCH(AG15,$B$83:$B$111,0),AH$49-1),0)=退所日,AG15,IF(IFERROR(INDEX($D$83:$AH$111,MATCH(AH15,$B$83:$B$111,0),AH$49-1),0)=連泊日,AH15,""))
D33: =IF(ISBLANK(D15),"",IF(OR(INDEX($D$83:$AH$111,MATCH(D15,$B$83:$B$111,0),D$49-1)={11,12}),D15,"")) | E33: =IF(ISBLANK(E15),"",IF(OR(INDEX($D$83:$AH$111,MATCH(E15,$B$83:$B$111,0),E$49-1)={11,12}),E15,"")) | F33: =IF(ISBLANK(F15),"",IF(OR(INDEX($D$83:$AH$111,MATCH(F15,$B$83:$B$111,0),F$49-1)={11,12}),F15,"")) -> 石井 | G33: =IF(ISBLANK(G15),"",IF(OR(INDEX($D$83:$AH$111,MATCH(G15,$B$83:$B$111,0),G$49-1)={11,12}),G15,"")) -> 石井 | H33: =IF(ISBLANK(H15),"",IF(OR(INDEX($D$83:$AH$111,MATCH(H15,$B$83:$B$111,0),H$49-1)={11,12}),H15,"")) | I33: =IF(ISBLANK(I15),"",IF(OR(INDEX($D$83:$AH$111,MATCH(I15,$B$83:$B$111,0),I$49-1)={11,12}),I15,"")) | J33: =IF(ISBLANK(J15),"",IF(OR(INDEX($D$83:$AH$111,MATCH(J15,$B$83:$B$111,0),J$49-1)={11,12}),J15,"")) | K33: =IF(ISBLANK(K15),"",IF(OR(INDEX($D$83:$AH$111,MATCH(K15,$B$83:$B$111,0),K$49-1)={11,12}),K15,"")) | ... AH33: =IF(ISBLANK(AH15),"",IF(OR(INDEX($D$83:$AH$111,MATCH(AH15,$B$83:$B$111,0),AH$49-1)={11,12}),AH15,""))
A34: 5号室 | D34: =IF(IFERROR(INDEX($D$83:$AH$111,MATCH(C16,$B$83:$B$111,0),D$49-1),0)=退所日,C16,IF(IFERROR(INDEX($D$83:$AH$111,MATCH(D16,$B$83:$B$111,0),D$49-1),0)=連泊日,D16,"")) | E34: =IF(IFERROR(INDEX($D$83:$AH$111,MATCH(D16,$B$83:$B$111,0),E$49-1),0)=退所日,D16,IF(IFERROR(INDEX($D$83:$AH$111,MATCH(E16,$B$83:$B$111,0),E$49-1),0)=連泊日,E16,"")) | F34: =IF(IFERROR(INDEX($D$83:$AH$111,MATCH(E16,$B$83:$B$111,0),F$49-1),0)=退所日,E16,IF(IFERROR(INDEX($D$83:$AH$111,MATCH(F16,$B$83:$B$111,0),F$49-1),0)=連泊日,F16,"")) -> 澤登 | G34: =IF(IFERROR(INDEX($D$83:$AH$111,MATCH(F16,$B$83:$B$111,0),G$49-1),0)=退所日,F16,IF(IFERROR(INDEX($D$83:$AH$111,MATCH(G16,$B$83:$B$111,0),G$49-1),0)=連泊日,G16,"")) -> 澤登 | H34: =IF(IFERROR(INDEX($D$83:$AH$111,MATCH(G16,$B$83:$B$111,0),H$49-1),0)=退所日,G16,IF(IFERROR(INDEX($D$83:$AH$111,MATCH(H16,$B$83:$B$111,0),H$49-1),0)=連泊日,H16,"")) -> 澤登 | I34: =IF(IFERROR(INDEX($D$83:$AH$111,MATCH(H16,$B$83:$B$111,0),I$49-1),0)=退所日,H16,IF(IFERROR(INDEX($D$83:$AH$111,MATCH(I16,$B$83:$B$111,0),I$49-1),0)=連泊日,I16,"")) -> 澤登 | J34: =IF(IFERROR(INDEX($D$83:$AH$111,MATCH(I16,$B$83:$B$111,0),J$49-1),0)=退所日,I16,IF(IFERROR(INDEX($D$83:$AH$111,MATCH(J16,$B$83:$B$111,0),J$49-1),0)=連泊日,J16,"")) -> 澤登 | K34: =IF(IFERROR(INDEX($D$83:$AH$111,MATCH(J16,$B$83:$B$111,0),K$49-1),0)=退所日,J16,IF(IFERROR(INDEX($D$83:$AH$111,MATCH(K16,$B$83:$B$111,0),K$49-1),0)=連泊日,K16,"")) | ... AH34: =IF(IFERROR(INDEX($D$83:$AH$111,MATCH(AG16,$B$83:$B$111,0),AH$49-1),0)=退所日,AG16,IF(IFERROR(INDEX($D$83:$AH$111,MATCH(AH16,$B$83:$B$111,0),AH$49-1),0)=連泊日,AH16,""))
D35: =IF(ISBLANK(D16),"",IF(OR(INDEX($D$83:$AH$111,MATCH(D16,$B$83:$B$111,0),D$49-1)={11,12}),D16,"")) | E35: =IF(ISBLANK(E16),"",IF(OR(INDEX($D$83:$AH$111,MATCH(E16,$B$83:$B$111,0),E$49-1)={11,12}),E16,"")) | F35: =IF(ISBLANK(F16),"",IF(OR(INDEX($D$83:$AH$111,MATCH(F16,$B$83:$B$111,0),F$49-1)={11,12}),F16,"")) -> 澤登 | G35: =IF(ISBLANK(G16),"",IF(OR(INDEX($D$83:$AH$111,MATCH(G16,$B$83:$B$111,0),G$49-1)={11,12}),G16,"")) -> 澤登 | H35: =IF(ISBLANK(H16),"",IF(OR(INDEX($D$83:$AH$111,MATCH(H16,$B$83:$B$111,0),H$49-1)={11,12}),H16,"")) -> 澤登 | I35: =IF(ISBLANK(I16),"",IF(OR(INDEX($D$83:$AH$111,MATCH(I16,$B$83:$B$111,0),I$49-1)={11,12}),I16,"")) -> 澤登 | J35: =IF(ISBLANK(J16),"",IF(OR(INDEX($D$83:$AH$111,MATCH(J16,$B$83:$B$111,0),J$49-1)={11,12}),J16,"")) -> 澤登 | K35: =IF(ISBLANK(K16),"",IF(OR(INDEX($D$83:$AH$111,MATCH(K16,$B$83:$B$111,0),K$49-1)={11,12}),K16,"")) | ... AH35: =IF(ISBLANK(AH16),"",IF(OR(INDEX($D$83:$AH$111,MATCH(AH16,$B$83:$B$111,0),AH$49-1)={11,12}),AH16,""))
A36: 6号室 | D36: =IF(IFERROR(INDEX($D$83:$AH$111,MATCH(C17,$B$83:$B$111,0),D$49-1),0)=退所日,C17,IF(IFERROR(INDEX($D$83:$AH$111,MATCH(D17,$B$83:$B$111,0),D$49-1),0)=連泊日,D17,"")) -> 吉田 | E36: =IF(IFERROR(INDEX($D$83:$AH$111,MATCH(D17,$B$83:$B$111,0),E$49-1),0)=退所日,D17,IF(IFERROR(INDEX($D$83:$AH$111,MATCH(E17,$B$83:$B$111,0),E$49-1),0)=連泊日,E17,"")) | F36: =IF(IFERROR(INDEX($D$83:$AH$111,MATCH(E17,$B$83:$B$111,0),F$49-1),0)=退所日,E17,IF(IFERROR(INDEX($D$83:$AH$111,MATCH(F17,$B$83:$B$111,0),F$49-1),0)=連泊日,F17,"")) -> 佐々 | G36: =IF(IFERROR(INDEX($D$83:$AH$111,MATCH(F17,$B$83:$B$111,0),G$49-1),0)=退所日,F17,IF(IFERROR(INDEX($D$83:$AH$111,MATCH(G17,$B$83:$B$111,0),G$49-1),0)=連泊日,G17,"")) -> 佐々 | H36: =IF(IFERROR(INDEX($D$83:$AH$111,MATCH(G17,$B$83:$B$111,0),H$49-1),0)=退所日,G17,IF(IFERROR(INDEX($D$83:$AH$111,MATCH(H17,$B$83:$B$111,0),H$49-1),0)=連泊日,H17,"")) -> 佐々 | I36: =IF(IFERROR(INDEX($D$83:$AH$111,MATCH(H17,$B$83:$B$111,0),I$49-1),0)=退所日,H17,IF(IFERROR(INDEX($D$83:$AH$111,MATCH(I17,$B$83:$B$111,0),I$49-1),0)=連泊日,I17,"")) | J36: =IF(IFERROR(INDEX($D$83:$AH$111,MATCH(I17,$B$83:$B$111,0),J$49-1),0)=退所日,I17,IF(IFERROR(INDEX($D$83:$AH$111,MATCH(J17,$B$83:$B$111,0),J$49-1),0)=連泊日,J17,"")) -> 吉田 | K36: =IF(IFERROR(INDEX($D$83:$AH$111,MATCH(J17,$B$83:$B$111,0),K$49-1),0)=退所日,J17,IF(IFERROR(INDEX($D$83:$AH$111,MATCH(K17,$B$83:$B$111,0),K$49-1),0)=連泊日,K17,"")) -> 吉田 | ... AH36: =IF(IFERROR(INDEX($D$83:$AH$111,MATCH(AG17,$B$83:$B$111,0),AH$49-1),0)=退所日,AG17,IF(IFERROR(INDEX($D$83:$AH$111,MATCH(AH17,$B$83:$B$111,0),AH$49-1),0)=連泊日,AH17,""))
D37: =IF(ISBLANK(D17),"",IF(OR(INDEX($D$83:$AH$111,MATCH(D17,$B$83:$B$111,0),D$49-1)={11,12}),D17,"")) | E37: =IF(ISBLANK(E17),"",IF(OR(INDEX($D$83:$AH$111,MATCH(E17,$B$83:$B$111,0),E$49-1)={11,12}),E17,"")) | F37: =IF(ISBLANK(F17),"",IF(OR(INDEX($D$83:$AH$111,MATCH(F17,$B$83:$B$111,0),F$49-1)={11,12}),F17,"")) -> 佐々 | G37: =IF(ISBLANK(G17),"",IF(OR(INDEX($D$83:$AH$111,MATCH(G17,$B$83:$B$111,0),G$49-1)={11,12}),G17,"")) -> 佐々 | H37: =IF(ISBLANK(H17),"",IF(OR(INDEX($D$83:$AH$111,MATCH(H17,$B$83:$B$111,0),H$49-1)={11,12}),H17,"")) | I37: =IF(ISBLANK(I17),"",IF(OR(INDEX($D$83:$AH$111,MATCH(I17,$B$83:$B$111,0),I$49-1)={11,12}),I17,"")) | J37: =IF(ISBLANK(J17),"",IF(OR(INDEX($D$83:$AH$111,MATCH(J17,$B$83:$B$111,0),J$49-1)={11,12}),J17,"")) -> 吉田 | K37: =IF(ISBLANK(K17),"",IF(OR(INDEX($D$83:$AH$111,MATCH(K17,$B$83:$B$111,0),K$49-1)={11,12}),K17,"")) -> 吉田 | ... AH37: =IF(ISBLANK(AH17),"",IF(OR(INDEX($D$83:$AH$111,MATCH(AH17,$B$83:$B$111,0),AH$49-1)={11,12}),AH17,""))
A38: 7号室 | D38: =IF(IFERROR(INDEX($D$83:$AH$111,MATCH(C18,$B$83:$B$111,0),D$49-1),0)=退所日,C18,IF(IFERROR(INDEX($D$83:$AH$111,MATCH(D18,$B$83:$B$111,0),D$49-1),0)=連泊日,D18,"")) -> 仲里 | E38: =IF(IFERROR(INDEX($D$83:$AH$111,MATCH(D18,$B$83:$B$111,0),E$49-1),0)=退所日,D18,IF(IFERROR(INDEX($D$83:$AH$111,MATCH(E18,$B$83:$B$111,0),E$49-1),0)=連泊日,E18,"")) | F38: =IF(IFERROR(INDEX($D$83:$AH$111,MATCH(E18,$B$83:$B$111,0),F$49-1),0)=退所日,E18,IF(IFERROR(INDEX($D$83:$AH$111,MATCH(F18,$B$83:$B$111,0),F$49-1),0)=連泊日,F18,"")) -> 山本 | G38: =IF(IFERROR(INDEX($D$83:$AH$111,MATCH(F18,$B$83:$B$111,0),G$49-1),0)=退所日,F18,IF(IFERROR(INDEX($D$83:$AH$111,MATCH(G18,$B$83:$B$111,0),G$49-1),0)=連泊日,G18,"")) -> 山本 | H38: =IF(IFERROR(INDEX($D$83:$AH$111,MATCH(G18,$B$83:$B$111,0),H$49-1),0)=退所日,G18,IF(IFERROR(INDEX($D$83:$AH$111,MATCH(H18,$B$83:$B$111,0),H$49-1),0)=連泊日,H18,"")) | I38: =IF(IFERROR(INDEX($D$83:$AH$111,MATCH(H18,$B$83:$B$111,0),I$49-1),0)=退所日,H18,IF(IFERROR(INDEX($D$83:$AH$111,MATCH(I18,$B$83:$B$111,0),I$49-1),0)=連泊日,I18,"")) -> 仲里 | J38: =IF(IFERROR(INDEX($D$83:$AH$111,MATCH(I18,$B$83:$B$111,0),J$49-1),0)=退所日,I18,IF(IFERROR(INDEX($D$83:$AH$111,MATCH(J18,$B$83:$B$111,0),J$49-1),0)=連泊日,J18,"")) -> 仲里 | K38: =IF(IFERROR(INDEX($D$83:$AH$111,MATCH(J18,$B$83:$B$111,0),K$49-1),0)=退所日,J18,IF(IFERROR(INDEX($D$83:$AH$111,MATCH(K18,$B$83:$B$111,0),K$49-1),0)=連泊日,K18,"")) -> 仲里 | ... AH38: =IF(IFERROR(INDEX($D$83:$AH$111,MATCH(AG18,$B$83:$B$111,0),AH$49-1),0)=退所日,AG18,IF(IFERROR(INDEX($D$83:$AH$111,MATCH(AH18,$B$83:$B$111,0),AH$49-1),0)=連泊日,AH18,""))
D39: =IF(ISBLANK(D18),"",IF(OR(INDEX($D$83:$AH$111,MATCH(D18,$B$83:$B$111,0),D$49-1)={11,12}),D18,"")) | E39: =IF(ISBLANK(E18),"",IF(OR(INDEX($D$83:$AH$111,MATCH(E18,$B$83:$B$111,0),E$49-1)={11,12}),E18,"")) | F39: =IF(ISBLANK(F18),"",IF(OR(INDEX($D$83:$AH$111,MATCH(F18,$B$83:$B$111,0),F$49-1)={11,12}),F18,"")) -> 山本 | G39: =IF(ISBLANK(G18),"",IF(OR(INDEX($D$83:$AH$111,MATCH(G18,$B$83:$B$111,0),G$49-1)={11,12}),G18,"")) | H39: =IF(ISBLANK(H18),"",IF(OR(INDEX($D$83:$AH$111,MATCH(H18,$B$83:$B$111,0),H$49-1)={11,12}),H18,"")) | I39: =IF(ISBLANK(I18),"",IF(OR(INDEX($D$83:$AH$111,MATCH(I18,$B$83:$B$111,0),I$49-1)={11,12}),I18,"")) -> 仲里 | J39: =IF(ISBLANK(J18),"",IF(OR(INDEX($D$83:$AH$111,MATCH(J18,$B$83:$B$111,0),J$49-1)={11,12}),J18,"")) -> 仲里 | K39: =IF(ISBLANK(K18),"",IF(OR(INDEX($D$83:$AH$111,MATCH(K18,$B$83:$B$111,0),K$49-1)={11,12}),K18,"")) | ... AH39: =IF(ISBLANK(AH18),"",IF(OR(INDEX($D$83:$AH$111,MATCH(AH18,$B$83:$B$111,0),AH$49-1)={11,12}),AH18,""))
A40: 8号室 | D40: =IF(IFERROR(INDEX($D$83:$AH$111,MATCH(C19,$B$83:$B$111,0),D$49-1),0)=退所日,C19,IF(IFERROR(INDEX($D$83:$AH$111,MATCH(D19,$B$83:$B$111,0),D$49-1),0)=連泊日,D19,"")) -> 二宮 | E40: =IF(IFERROR(INDEX($D$83:$AH$111,MATCH(D19,$B$83:$B$111,0),E$49-1),0)=退所日,D19,IF(IFERROR(INDEX($D$83:$AH$111,MATCH(E19,$B$83:$B$111,0),E$49-1),0)=連泊日,E19,"")) | F40: =IF(IFERROR(INDEX($D$83:$AH$111,MATCH(E19,$B$83:$B$111,0),F$49-1),0)=退所日,E19,IF(IFERROR(INDEX($D$83:$AH$111,MATCH(F19,$B$83:$B$111,0),F$49-1),0)=連泊日,F19,"")) -> 星野 | G40: =IF(IFERROR(INDEX($D$83:$AH$111,MATCH(F19,$B$83:$B$111,0),G$49-1),0)=退所日,F19,IF(IFERROR(INDEX($D$83:$AH$111,MATCH(G19,$B$83:$B$111,0),G$49-1),0)=連泊日,G19,"")) -> 星野 | H40: =IF(IFERROR(INDEX($D$83:$AH$111,MATCH(G19,$B$83:$B$111,0),H$49-1),0)=退所日,G19,IF(IFERROR(INDEX($D$83:$AH$111,MATCH(H19,$B$83:$B$111,0),H$49-1),0)=連泊日,H19,"")) -> 星野 | I40: =IF(IFERROR(INDEX($D$83:$AH$111,MATCH(H19,$B$83:$B$111,0),I$49-1),0)=退所日,H19,IF(IFERROR(INDEX($D$83:$AH$111,MATCH(I19,$B$83:$B$111,0),I$49-1),0)=連泊日,I19,"")) -> 星野 | J40: =IF(IFERROR(INDEX($D$83:$AH$111,MATCH(I19,$B$83:$B$111,0),J$49-1),0)=退所日,I19,IF(IFERROR(INDEX($D$83:$AH$111,MATCH(J19,$B$83:$B$111,0),J$49-1),0)=連泊日,J19,"")) -> 二宮 | K40: =IF(IFERROR(INDEX($D$83:$AH$111,MATCH(J19,$B$83:$B$111,0),K$49-1),0)=退所日,J19,IF(IFERROR(INDEX($D$83:$AH$111,MATCH(K19,$B$83:$B$111,0),K$49-1),0)=連泊日,K19,"")) -> 二宮 | ... AH40: =IF(IFERROR(INDEX($D$83:$AH$111,MATCH(AG19,$B$83:$B$111,0),AH$49-1),0)=退所日,AG19,IF(IFERROR(INDEX($D$83:$AH$111,MATCH(AH19,$B$83:$B$111,0),AH$49-1),0)=連泊日,AH19,""))
D41: =IF(ISBLANK(D19),"",IF(OR(INDEX($D$83:$AH$111,MATCH(D19,$B$83:$B$111,0),D$49-1)={11,12}),D19,"")) | E41: =IF(ISBLANK(E19),"",IF(OR(INDEX($D$83:$AH$111,MATCH(E19,$B$83:$B$111,0),E$49-1)={11,12}),E19,"")) | F41: =IF(ISBLANK(F19),"",IF(OR(INDEX($D$83:$AH$111,MATCH(F19,$B$83:$B$111,0),F$49-1)={11,12}),F19,"")) -> 星野 | G41: =IF(ISBLANK(G19),"",IF(OR(INDEX($D$83:$AH$111,MATCH(G19,$B$83:$B$111,0),G$49-1)={11,12}),G19,"")) -> 星野 | H41: =IF(ISBLANK(H19),"",IF(OR(INDEX($D$83:$AH$111,MATCH(H19,$B$83:$B$111,0),H$49-1)={11,12}),H19,"")) -> 星野 | I41: =IF(ISBLANK(I19),"",IF(OR(INDEX($D$83:$AH$111,MATCH(I19,$B$83:$B$111,0),I$49-1)={11,12}),I19,"")) -> 星野 | J41: =IF(ISBLANK(J19),"",IF(OR(INDEX($D$83:$AH$111,MATCH(J19,$B$83:$B$111,0),J$49-1)={11,12}),J19,"")) -> 二宮 | K41: =IF(ISBLANK(K19),"",IF(OR(INDEX($D$83:$AH$111,MATCH(K19,$B$83:$B$111,0),K$49-1)={11,12}),K19,"")) | ... AH41: =IF(ISBLANK(AH19),"",IF(OR(INDEX($D$83:$AH$111,MATCH(AH19,$B$83:$B$111,0),AH$49-1)={11,12}),AH19,""))
A42: 9号室 | D42: =IF(IFERROR(INDEX($D$83:$AH$111,MATCH(C20,$B$83:$B$111,0),D$49-1),0)=退所日,C20,IF(IFERROR(INDEX($D$83:$AH$111,MATCH(D20,$B$83:$B$111,0),D$49-1),0)=連泊日,D20,"")) | E42: =IF(IFERROR(INDEX($D$83:$AH$111,MATCH(D20,$B$83:$B$111,0),E$49-1),0)=退所日,D20,IF(IFERROR(INDEX($D$83:$AH$111,MATCH(E20,$B$83:$B$111,0),E$49-1),0)=連泊日,E20,"")) -> 伊シ | F42: =IF(IFERROR(INDEX($D$83:$AH$111,MATCH(E20,$B$83:$B$111,0),F$49-1),0)=退所日,E20,IF(IFERROR(INDEX($D$83:$AH$111,MATCH(F20,$B$83:$B$111,0),F$49-1),0)=連泊日,F20,"")) -> 伊シ | G42: =IF(IFERROR(INDEX($D$83:$AH$111,MATCH(F20,$B$83:$B$111,0),G$49-1),0)=退所日,F20,IF(IFERROR(INDEX($D$83:$AH$111,MATCH(G20,$B$83:$B$111,0),G$49-1),0)=連泊日,G20,"")) -> 伊シ | H42: =IF(IFERROR(INDEX($D$83:$AH$111,MATCH(G20,$B$83:$B$111,0),H$49-1),0)=退所日,G20,IF(IFERROR(INDEX($D$83:$AH$111,MATCH(H20,$B$83:$B$111,0),H$49-1),0)=連泊日,H20,"")) -> 伊シ | I42: =IF(IFERROR(INDEX($D$83:$AH$111,MATCH(H20,$B$83:$B$111,0),I$49-1),0)=退所日,H20,IF(IFERROR(INDEX($D$83:$AH$111,MATCH(I20,$B$83:$B$111,0),I$49-1),0)=連泊日,I20,"")) -> 伊シ | J42: =IF(IFERROR(INDEX($D$83:$AH$111,MATCH(I20,$B$83:$B$111,0),J$49-1),0)=退所日,I20,IF(IFERROR(INDEX($D$83:$AH$111,MATCH(J20,$B$83:$B$111,0),J$49-1),0)=連泊日,J20,"")) -> 伊シ | K42: =IF(IFERROR(INDEX($D$83:$AH$111,MATCH(J20,$B$83:$B$111,0),K$49-1),0)=退所日,J20,IF(IFERROR(INDEX($D$83:$AH$111,MATCH(K20,$B$83:$B$111,0),K$49-1),0)=連泊日,K20,"")) -> 伊シ | ... AH42: =IF(IFERROR(INDEX($D$83:$AH$111,MATCH(AG20,$B$83:$B$111,0),AH$49-1),0)=退所日,AG20,IF(IFERROR(INDEX($D$83:$AH$111,MATCH(AH20,$B$83:$B$111,0),AH$49-1),0)=連泊日,AH20,""))
...

Sheet 宿泊欄自動割当
A1: 1 | B1: =【入力・帳票】ベッド表!C1 -> 安藤 | C1: =【入力・帳票】ベッド表!D1 -> 伊シ | D1: =【入力・帳票】ベッド表!E1 -> 安藤 | E1: =【入力・帳票】ベッド表!F1 -> 安藤 | F1: =【入力・帳票】ベッド表!G1 -> 石井 | G1: =【入力・帳票】ベッド表!H1 -> 伊シ | H1: =【入力・帳票】ベッド表!I1 -> 安藤 | I1: =【入力・帳票】ベッド表!J1 -> 安藤 | ... AG1: =【入力・帳票】ベッド表!AH1 -> 安藤
